Workbook
Name Months: [1]Admin!$A$1:$A$48
Name rawdata: 'raw data'!$1:$1048576
Name Reported: 'raw data'!$D:$D,'raw data'!$F:$F,'raw data'!$H:$H

Sheet raw data
D1: 40513 | F1: 40544 | H1: 40575 | J1: 40603 | L1: 40634 | N1: 40664 | P1: 40695 | R1: 40725 | T1: 40756 | V1: 40787 | X1: 40817 | Z1: 40848 | AB1: 40878 | AD1: 40909 | AF1: 40940 | AH1: 40969 | AJ1: 41000 | AL1: 41030 | AN1: 41061 | AP1: 41091 | AR1: 41122 | AT1: 41153 | AV1: 41183 | AX1: 41214 | AZ1: 41244 | BB1: 41275 | BD1: 41306 | BF1: 41334 | BH1: 41365 | BJ1: 41395 | BL1: 41426 | BN1: 41456 | BP1: 41487 | BR1: 41518 | BT1: 41548 | BV1: 41579 | BX1: 41609 | BZ1: 41640 | CB1: 41671 | CD1: 41699 | CF1: 41730 | CH1: 41760 | CJ1: 41791 | CL1: 41821 | CN1: 41852 | CP1: 41883 | CR1: 41913 | CT1: 41944 | CV1: 41974 | CX1: 42005 | CZ1: 42036 | DB1: 42064 | DD1: 42095 | DF1: 42125 | DH1: 42156 | DJ1: 42186 | DL1: 42217 | DN1: 42248 | DP1: 42278 | DR1: 42309 | DT1: 42339 | DV1: 42370 | DX1: 42401 | DZ1: 42430 | EB1: 42461 | ED1: 42491 | EF1: 42522 | EH1: 42552 | EJ1: 42583 | EL1: 42614 | EN1: 42644 | EP1: 42675 | ER1: 42705 | ET1: 42736 | EV1: 42767 | EX1: 42795 | EZ1: 42826 | FB1: 42856 | FD1: 42887 | FF1: 42917 | FH1: 42948 | FJ1: 42979 | FN1: 43009 | FP1: 43040 | FR1: 43070 | FT1: 43101 | FV1: 43132 | FX1: 43160 | FZ1: 43191 | GB1: 43221 | GD1: 43252 | GF1: 43282 | GH1: 43313 | GJ1: 43344 | GL1: 43374 | GN1: 43405 | GP1: 43435 | GR1: 43466 | GT1: 43497 | GV1: 43525 | GX1: 43556 | GZ1: 43586 | HB1: 43617 | HD1: 43647 | HF1: 43678 | HH1: 43709 | HJ1: 43739 | HL1: 43770 | HN1: 43800 | HP1: 43831 | HR1: 43862 | HT1: 43891 | HV1: 43922 | HX1: 43952 | HZ1: 43983 | IB1: 44013 | ID1: 44044 | IF1: 44075 | IH1: 44105 | IJ1: 44136 | IL1: 44166 | IN1: 44197 | IP1: 44228 | IR1: 44256 | IT1: 44287 | IV1: 44317 | IX1: 44348 | IZ1: 44378 | JB1: 44409 | JD1: 44440
D2: Reported | E2: Alerts | F2: Reported | G2: Alerts | H2: Reported | I2: Alerts | J2: Reported | K2: Alerts | L2: Reported | M2: Alerts | N2: Reported | O2: Alerts | P2: Reported | Q2: Alerts | R2: Reported | S2: Alerts | T2: Reported | U2: Alerts | V2: Reported | W2: Alerts | X2: Reported | Y2: Alerts | Z2: Reported | AA2: Alerts | AB2: Reported | AC2: Alerts | AD2: Reported | AE2: Alerts | AF2: Reported | AG2: Alerts | AH2: Reported | AI2: Alerts | AJ2: Reported | AK2: Alerts | AL2: Reported | AM2: Alerts | AN2: Reported | AO2: Alerts | AP2: Reported | AQ2: Alerts | AR2: Reported | AS2: Alerts | AT2: Reported | AU2: Alerts | AV2: Reported | AW2: Alerts | AX2: Reported | AY2: Alerts | AZ2: Reported | BA2: Alerts | BB2: Reported | BC2: Alerts | BD2: Reported | BE2: Alerts | BF2: Reported | BG2: Alerts | BH2: Reported | BI2: Alerts | BJ2: Reported | BK2: Alerts | BL2: Reported | BM2: Alerts | BN2: Reported | BO2: Alerts | BP2: Reported | BQ2: Alerts | BR2: Reported | BS2: Alerts | BT2: Reported | BU2: Alerts | BV2: Reported | BW2: Alerts | BX2: Reported | BY2: Alerts | BZ2: Reported | CA2: Alerts | CB2: Reported | CC2: Alerts | CD2: Reported | CE2: Alerts | CF2: Reported | CG2: Alerts | CH2: Reported | CI2: Alerts | CJ2: Reported | CK2: Alerts | CL2: Reported | CM2: Alerts | CN2: Reported | CO2: Alerts | CP2: Reported | CQ2: Alerts | CR2: Reported | CS2: Alerts | CT2: Reported | CU2: Alerts | CV2: Reported | CW2: Alerts | CX2: Reported | CY2: Alerts | CZ2: Reported | DA2: Alerts | DB2: Reported | DC2: Alerts | DD2: Reported | DE2: Alerts | DF2: Reported | DG2: Alerts | DH2: Reported | DI2: Alerts | DJ2: Reported | DK2: Alerts | DL2: Reported | DM2: Alerts | DN2: Reported | DO2: Alerts | DP2: Reported | DQ2: Alerts | DR2: Reported | DS2: Alerts | DT2: Reported | DU2: Alerts | DV2: Reported | DW2: Alerts | DX2: Reported | DY2: Alerts | DZ2: Reported | EA2: Alerts | EB2: Reported | EC2: Alerts | ED2: Reported | EE2: Alerts | EF2: Reported | EG2: Alerts | EH2: Reported | EI2: Alerts | EJ2: Reported | EK2: Alerts | EL2: Reported | EM2: Alerts | EN2: Reported | EO2: Alerts | EP2: Reported | EQ2: Alerts | ER2: Reported | ES2: Alerts | ET2: Reported | EU2: Alerts | EV2: Reported | EW2: Alerts | EX2: Reported | EY2: Alerts | EZ2: Reported | FA2: Alerts | FB2: Reported | FC2: Alerts | FD2: Reported | FE2: Alerts | FF2: Reported | FG2: Alerts | FH2: Reported | FI2: Alerts | FJ2: Reported | FK2: Take 1 Alerts | FL2: Take2 12/10/17 | FM2: Alerts | FN2: Reported | FO2: Alerts | FP2: Reported | FQ2: Alerts | FR2: Reported | FS2: Alerts | FT2: Reported | FU2: Alerts | FV2: Reported | FW2: Alerts | FX2: Reported | FY2: Alerts | FZ2: Reported | GA2: Alerts | GB2: Reported | GC2: Alerts | GD2: Reported | GE2: Alerts | GF2: Reported | GG2: Alerts | GH2: Reported | GI2: Alerts | GJ2: Reported | GK2: Alerts | GL2: Reported | GM2: Alerts | GN2: Reported | GO2: Alerts | GP2: Reported | GQ2: Alerts | GR2: Reported | GS2: Alerts | GT2: Reported | GU2: Alerts | GV2: Reported | GW2: Alerts | GX2: Reported | GY2: Alerts | GZ2: Reported | HA2: Alerts | HB2: Reported | HC2: Alerts | HD2: Reported | HE2: Alerts | HF2: Reported | HG2: Alerts | HH2: Reported | HI2: Alerts | HJ2: Reported | HK2: Alerts | HL2: Reported | HM2: Alerts | HN2: Reported | HO2: Alerts | HP2: Reported | HQ2: Alerts | HR2: Reported | HS2: Alerts | HT2: Reported | HU2: Alerts | HV2: Reported | HW2: Alerts | HX2: Reported | HY2: Alerts | HZ2: Reported | IA2: Alerts | IB2: Reported | IC2: Alerts | ID2: Reported | IE2: Alerts | IF2: Reported | IG2: Alerts | IH2: Reported | II2: Alerts | IJ2: Reported | IK2: Alerts | IL2: Reported | IM2: Alerts | IN2: Reported | IO2: Alerts | IP2: Reported | IQ2: Alerts | IR2: Reported | IS2: Alerts | IT2: Reported | IU2: Alerts | IV2: Reported | IW2: Alerts | IX2: Reported | IY2: Alerts | IZ2: Reported | JA2: Alerts | JB2: Reported | JC2: Alerts | JD2: Reported | JE2: Alerts
A3: 1.1 | B3: Flex accounts with >=2 cash credits (CR) & at least 1 withdrawal (WD) in same day (occurred at least three times last month). | C3: Flex Accounts with >2 Cash Credits per Day with withdrawal the same day | D3: 28 | E3: 56 | F3: 14 | G3: 36 | H3: 18 | I3: 50 | J3: 18 | K3: 68 | L3: 9 | M3: 55 | N3: 19 | O3: 69 | P3: 3 | Q3: 19 | R3: 27 | S3: 83 | T3: 17 | U3: 71 | V3: 19 | W3: 75 | X3: 16 | Y3: 67 | Z3: 14 | AA3: 59 | AB3: 16 | AC3: 75 | AD3: 6 | AE3: 36 | AF3: 11 | AG3: 49 | AH3: 20 | AI3: 73 | AJ3: 16 | AK3: 43 | AL3: 6 | AM3: 45 | AN3: 7 | AO3: 26 | AP3: 11 | AQ3: 39 | AR3: 18 | AS3: 40 | AT3: 11 | AU3: 30 | AV3: 10 | AW3: 42 | AX3: 6 | AY3: 33 | AZ3: 9 | BA3: 30 | BB3: 11 | BC3: 37 | BD3: 14 | BE3: 34 | BF3: 12 | BG3: 42 | BH3: 10 | BI3: 30 | BJ3: 4 | BK3: 31 | BL3: 4 | BM3: 27 | BN3: 9 | BO3: 40 | BP3: 3 | BQ3: 30 | BR3: 10 | BS3: 40 | BT3: 10 | BU3: 46 | BV3: 10 | BW3: 39 | BX3: 8 | BY3: 36 | BZ3: 11 | CA3: 53 | CB3: 14 | CC3: 77 | CD3: 16 | CE3: 48 | CF3: 4 | CG3: 12 | CH3: 17 | CI3: 49 | CJ3: 9 | CK3: 38 | CL3: 13 | CM3: 57 | CN3: 9 | CO3: 32 | CP3: 22 | CQ3: 62 | CR3: 10 | CS3: 40 | CT3: 10 | CU3: 33 | CV3: 14 | CW3: 37 | CX3: 10 | CY3: 37 | CZ3: 13 | DA3: 30 | DB3: 17 | DC3: 40 | DD3: 16 | DE3: 44 | DF3: 15 | DG3: 50 | DH3: 12 | DI3: 38 | DJ3: 17 | DK3: 50 | DL3: 13 | DM3: 45 | DN3: 24 | DO3: 49 | DP3: 25 | DQ3: 58 | DR3: 11 | DS3: 31 | DT3: 14 | DU3: 39 | DV3: 10 | DW3: 43 | DX3: 11 | DY3: 34 | DZ3: 7 | EA3: 40 | EB3: 18 | EC3: 42 | ED3: 7 | EE3: 39 | EF3: 16 | EG3: 53 | EH3: 8 | EI3: 45 | EJ3: 15 | EK3: 58 | EL3: 11 | EM3: 35 | EN3: 10 | EO3: 33 | EP3: 12 | EQ3: 41 | ER3: 19 | ES3: 44 | ET3: 11 | EU3: 36 | EV3: 9 | EW3: 34 | EX3: 17 | EY3: 58 | EZ3: 13 | FA3: 41 | FB3: 15 | FC3: 55 | FD3: 14 | FE3: 53 | FF3: 18 | FG3: 49 | FH3: 10 | FI3: 43 | FJ3: 11 | FK3: 46 | FL3: 46 | FM3: 46 | FN3: 1 | FO3: 10 | FP3: 5 | FQ3: 18 | FR3: 4 | FS3: 11 | FT3: 5 | FU3: 13 | FV3: 1 | FW3: 11 | FX3: 1 | FY3: 7 | FZ3: 1 | GA3: 5 | GB3: 1 | GC3: 3 | GD3: 1 | GE3: 6 | GF3: 2 | GG3: 15 | GH3: 4 | GI3: 10 | GJ3: 1 | GK3: 4 | GL3: 3 | GM3: 9 | GN3: 3 | GO3: 9 | GP3: 2 | GQ3: 6 | GR3: 3 | GS3: 8 | GT3: 2 | GU3: 5 | GV3: 2 | GW3: 9 | GX3: 2 | GY3: 6 | GZ3: 1 | HA3: 2 | HB3: 0 | HC3: 2 | HD3: 1 | HE3: 8 | HF3: 1 | HG3: 4 | HH3: 0 | HI3: 6 | HJ3: 2 | HK3: 6 | HL3: 1 | HM3: 8 | HN3: 1 | HO3: 4 | HP3: 4 | HQ3: 7 | HR3: 2 | HS3: 3 | HT3: 2 | HU3: 6 | HV3: 1 | HW3: 6 | HX3: 1 | HY3: 11 | HZ3: 1 | IA3: 12 | IB3: 2 | IC3: 7 | ID3: 1 | IE3: 3 | IF3: 4 | IG3: 7 | IH3: 0 | II3: 3 | IJ3: 1 | IK3: 5 | IL3: 1 | IM3: 1 | IN3: 1 | IO3: 1 | IP3: 0 | IQ3: 1 | IR3: 1 | IS3: 1 | IT3: 0 | IU3: 1 | IV3: 1 | IW3: 3 | IX3: 3 | IY3: 4 | IZ3: 0 | JA3: 2 | JB3: 2 | JC3: 4 | JD3: 3 | JE3: 6
A4: 1.2 | B4: Savings accounts with >=2 cash credits (CR) & at least 1 withdrawal (WD) in same day (occurred at least three times in month). | C4: Save Accounts with >2 Cash Credits per Day with withdrawal the same day | D4: 14 | E4: 26 | F4: 7 | G4: 20 | H4: 2 | I4: 16 | J4: 16 | K4: 48 | L4: 9 | M4: 28 | N4: 20 | O4: 41 | P4: 0 | Q4: 11 | R4: 10 | S4: 42 | T4: 6 | U4: 33 | V4: 6 | W4: 32 | X4: 4 | Y4: 23 | Z4: 6 | AA4: 30 | AB4: 8 | AC4: 25 | AD4: 4 | AE4: 13 | AF4: 2 | AG4: 15 | AH4: 2 | AI4: 13 | AJ4: 3 | AK4: 13 | AL4: 1 | AM4: 15 | AN4: 3 | AO4: 13 | AP4: 3 | AQ4: 17 | AR4: 2 | AS4: 13 | AT4: 4 | AU4: 14 | AV4: 6 | AW4: 19 | AX4: 3 | AY4: 11 | AZ4: 3 | BA4: 10 | BB4: 2 | BC4: 13 | BD4: 5 | BE4: 15 | BF4: 3 | BG4: 17 | BH4: 6 | BI4: 16 | BJ4: 2 | BK4: 16 | BL4: 2 | BM4: 27 | BN4: 2 | BO4: 26 | BP4: 2 | BQ4: 11 | BR4: 1 | BS4: 24 | BT4: 1 | BU4: 15 | BV4: 5 | BW4: 20 | BX4: 3 | BY4: 17 | BZ4: 3 | CA4: 16 | CB4: 2 | CC4: 11 | CD4: 6 | CE4: 17 | CF4: 0 | CG4: 6 | CH4: 5 | CI4: 17 | CJ4: 3 | CK4: 15 | CL4: 5 | CM4: 17 | CN4: 2 | CO4: 10 | CP4: 1 | CQ4: 14 | CR4: 2 | CS4: 13 | CT4: 4 | CU4: 17 | CV4: 6 | CW4: 23 | CX4: 2 | CY4: 18 | CZ4: 1 | DA4: 8 | DB4: 5 | DC4: 13 | DD4: 2 | DE4: 11 | DF4: 5 | DG4: 12 | DH4: 4 | DI4: 17 | DJ4: 8 | DK4: 19 | DL4: 7 | DM4: 20 | DN4: 2 | DO4: 13 | DP4: 7 | DQ4: 15 | DR4: 2 | DS4: 11 | DT4: 3 | DU4: 13 | DV4: 2 | DW4: 11 | DX4: 0 | DY4: 7 | DZ4: 1 | EA4: 18 | EB4: 3 | EC4: 15 | ED4: 6 | EE4: 15 | EF4: 2 | EG4: 11 | EH4: 2 | EI4: 11 | EJ4: 2 | EK4: 17 | EL4: 4 | EM4: 22 | EN4: 1 | EO4: 11 | EP4: 2 | EQ4: 11 | ER4: 5 | ES4: 11 | ET4: 2 | EU4: 10 | EV4: 2 | EW4: 12 | EX4: 1 | EY4: 9 | EZ4: 2 | FA4: 12 | FB4: 4 | FC4: 15 | FD4: 1 | FE4: 12 | FF4: 4 | FG4: 9 | FH4: 3 | FI4: 10 | FJ4: 1 | FK4: 8 | FL4: 8 | FM4: 8 | FN4: 0 | FO4: 2 | FP4: 0 | FQ4: 1 | FR4: 0 | FS4: 2 | FT4: 0 | FU4: 3 | FV4: 3 | FW4: 5 | FX4: 0 | FY4: 0 | FZ4: 0 | GA4: 0 | GB4: 0 | GC4: 2 | GD4: 0 | GE4: 2 | GF4: 1 | GG4: 2 | GH4: 0 | GI4: 0 | GJ4: 0 | GK4: 0 | GL4: 1 | GM4: 3 | GN4: 0 | GO4: 3 | GP4: 0 | GQ4: 0 | GR4: 0 | GS4: 0 | GT4: 0 | GU4: 1 | GV4: 0 | GW4: 0 | GX4: 0 | GY4: 0 | GZ4: 0 | HA4: 0 | HB4: 1 | HC4: 1 | HD4: 0 | HE4: 0 | HF4: 0 | HG4: 0 | HH4: 0 | HI4: 0 | HJ4: 0 | HK4: 0 | HL4: 0 | HM4: 0 | HN4: 1 | HO4: 1 | HP4: 0 | HQ4: 0 | HR4: 0 | HS4: 0 | HT4: 0 | HU4: 0 | HV4: 0 | HW4: 1 | HX4: 0 | HY4: 2 | HZ4: 0 | IA4: 0 | IB4: 0 | IC4: 1 | ID4: 1 | IE4: 2 | IF4: 0 | IG4: 2 | IH4: 0 | II4: 1 | IJ4: 0 | IK4: 0 | IL4: 0 | IM4: 1 | IN4: 0 | IO4: 0 | IP4: 0 | IQ4: 0 | IR4: 0 | IS4: 0 | IT4: 0 | IU4: 0 | IV4: 0 | IW4: 1 | IX4: 0 | IY4: 0 | IZ4: 0 | JA4: 0 | JB4: 0 | JC4: 0 | JD4: 0 | JE4: 0
A5: 1.3 | B5: Flex accounts with large number (7+) of branches used (CR, CQ, WD) and min cash credits of £1k per month. | C5: Flex Accs with >6 branches used | D5: 16 | E5: 27 | F5: 6 | G5: 9 | H5: 3 | I5: 8 | J5: 9 | K5: 28 | L5: 6 | M5: 28 | N5: 10 | O5: 27 | P5: 1 | Q5: 4 | R5: 6 | S5: 23 | T5: 15 | U5: 38 | V5: 27 | W5: 42 | X5: 10 | Y5: 29 | Z5: 10 | AA5: 37 | AB5: 7 | AC5: 27 | AD5: 4 | AE5: 9 | AF5: 8 | AG5: 13 | AH5: 18 | AI5: 38 | AJ5: 7 | AK5: 21 | AL5: 7 | AM5: 15 | AN5: 7 | AO5: 16 | AP5: 11 | AQ5: 21 | AR5: 9 | AS5: 16 | AT5: 18 | AU5: 40 | AV5: 50 | AW5: 112 | AX5: 34 | AY5: 65 | AZ5: 12 | BA5: 47 | BB5: 43 | BC5: 78 | BD5: 20 | BE5: 59 | BF5: 29 | BG5: 72 | BH5: 28 | BI5: 76 | BJ5: 20 | BK5: 66 | BL5: 21 | BM5: 65 | BN5: 33 | BO5: 97 | BP5: 22 | BQ5: 70 | BR5: 24 | BS5: 70 | BT5: 27 | BU5: 95 | BV5: 23 | BW5: 66 | BX5: 32 | BY5: 75 | BZ5: 16 | CA5: 62 | CB5: 25 | CC5: 83 | CD5: 35 | CE5: 77 | CF5: 32 | CG5: 80 | CH5: 27 | CI5: 77 | CJ5: 17 | CK5: 54 | CL5: 50 | CM5: 140 | CN5: 35 | CO5: 90 | CP5: 41 | CQ5: 100 | CR5: 32 | CS5: 92 | CT5: 44 | CU5: 102 | CV5: 42 | CW5: 91 | CX5: 46 | CY5: 83 | CZ5: 42 | DA5: 76 | DB5: 56 | DC5: 115 | DD5: 66 | DE5: 119 | DF5: 45 | DG5: 94 | DH5: 51 | DI5: 91 | DJ5: 62 | DK5: 125 | DL5: 54 | DM5: 130 | DN5: 53 | DO5: 119 | DP5: 43 | DQ5: 84 | DR5: 43 | DS5: 77 | DT5: 64 | DU5: 100 | DV5: 29 | DW5: 75 | DX5: 26 | DY5: 72 | DZ5: 29 | EA5: 76 | EB5: 60 | EC5: 109 | ED5: 36 | EE5: 80 | EF5: 40 | EG5: 101 | EH5: 37 | EI5: 91 | EJ5: 56 | EK5: 115 | EL5: 34 | EM5: 97 | EN5: 56 | EO5: 102 | EP5: 59 | EQ5: 106 | ER5: 44 | ES5: 88 | ET5: 35 | EU5: 73 | EV5: 48 | EW5: 98 | EX5: 49 | EY5: 103 | EZ5: 35 | FA5: 66 | FB5: 48 | FC5: 104 | FD5: 42 | FE5: 99 | FF5: 50 | FG5: 95 | FH5: 37 | FI5: 84 | FJ5: 42 | FK5: 90 | FL5: 90 | FM5: 90 | FN5: 37 | FO5: 106 | FP5: 12 | FQ5: 25 | FR5: 13 | FS5: 17 | FT5: 5 | FU5: 13 | FV5: 5 | FW5: 20 | FX5: 2 | FY5: 6 | FZ5: 2 | GA5: 3 | GB5: 0 | GC5: 0 | GD5: 0 | GE5: 0 | GF5: 0 | GG5: 3 | GH5: 0 | GI5: 1 | GJ5: 1 | GK5: 2 | GL5: 0 | GM5: 1 | GN5: 1 | GO5: 5 | GP5: 1 | GQ5: 2 | GR5: 0 | GS5: 1 | GT5: 0 | GU5: 0 | GV5: 1 | GW5: 2 | GX5: 0 | GY5: 2 | GZ5: 0 | HA5: 2 | HB5: 1 | HC5: 1 | HD5: 0 | HE5: 1 | HF5: 0 | HG5: 0 | HH5: 0 | HI5: 1 | HJ5: 1 | HK5: 4 | HL5: 0 | HM5: 0 | HN5: 0 | HO5: 1 | HP5: 1 | HQ5: 4 | HR5: 0 | HS5: 0 | HT5: 1 | HU5: 1 | HV5: 0 | HW5: 0 | HX5: 0 | HY5: 1 | HZ5: 0 | IA5: 0 | IB5: 0 | IC5: 0 | ID5: 0 | IE5: 0 | IF5: 0 | IG5: 0 | IH5: 0 | II5: 0 | IJ5: 0 | IK5: 0 | IL5: 0 | IM5: 0 | IN5: 0 | IO5: 0 | IP5: 0 | IQ5: 0 | IR5: 0 | IS5: 0 | IT5: 0 | IU5: 0 | IV5: 0 | IW5: 0 | IX5: 0 | IY5: 0 | IZ5: 0 | JA5: 0 | JB5: 0 | JC5: 0 | JD5: 0 | JE5: 0
A6: 1.4 | B6: Savings accounts with large number (7+) of branches used (CR, CQ, WD) and min cash credits of £1k per month. | C6: Save Accs with >6 branches used | D6: 6 | E6: 20 | F6: 3 | G6: 8 | H6: 0 | I6: 5 | J6: 5 | K6: 17 | L6: 1 | M6: 8 | N6: 6 | O6: 16 | P6: 0 | Q6: 5 | R6: 2 | S6: 13 | T6: 3 | U6: 10 | V6: 5 | W6: 15 | X6: 3 | Y6: 9 | Z6: 6 | AA6: 20 | AB6: 3 | AC6: 7 | AD6: 1 | AE6: 4 | AF6: 2 | AG6: 5 | AH6: 4 | AI6: 6 | AJ6: 4 | AK6: 10 | AL6: 2 | AM6: 7 | AN6: 1 | AO6: 4 | AP6: 2 | AQ6: 7 | AR6: 0 | AS6: 3 | AT6: 6 | AU6: 19 | AV6: 14 | AW6: 44 | AX6: 7 | AY6: 35 | AZ6: 3 | BA6: 25 | BB6: 6 | BC6: 35 | BD6: 4 | BE6: 15 | BF6: 5 | BG6: 47 | BH6: 1 | BI6: 30 | BJ6: 2 | BK6: 32 | BL6: 3 | BM6: 35 | BN6: 7 | BO6: 38 | BP6: 6 | BQ6: 29 | BR6: 5 | BS6: 35 | BT6: 7 | BU6: 40 | BV6: 5 | BW6: 33 | BX6: 9 | BY6: 37 | BZ6: 6 | CA6: 33 | CB6: 7 | CC6: 27 | CD6: 8 | CE6: 38 | CF6: 10 | CG6: 33 | CH6: 8 | CI6: 36 | CJ6: 3 | CK6: 36 | CL6: 19 | CM6: 53 | CN6: 9 | CO6: 30 | CP6: 7 | CQ6: 34 | CR6: 4 | CS6: 41 | CT6: 13 | CU6: 36 | CV6: 4 | CW6: 35 | CX6: 12 | CY6: 41 | CZ6: 12 | DA6: 33 | DB6: 14 | DC6: 46 | DD6: 5 | DE6: 28 | DF6: 10 | DG6: 38 | DH6: 11 | DI6: 38 | DJ6: 13 | DK6: 39 | DL6: 13 | DM6: 43 | DN6: 12 | DO6: 43 | DP6: 9 | DQ6: 34 | DR6: 8 | DS6: 35 | DT6: 9 | DU6: 36 | DV6: 4 | DW6: 15 | DX6: 5 | DY6: 32 | DZ6: 12 | EA6: 45 | EB6: 5 | EC6: 25 | ED6: 6 | EE6: 33 | EF6: 4 | EG6: 37 | EH6: 6 | EI6: 36 | EJ6: 9 | EK6: 48 | EL6: 9 | EM6: 35 | EN6: 3 | EO6: 31 | EP6: 5 | EQ6: 22 | ER6: 9 | ES6: 19 | ET6: 7 | EU6: 25 | EV6: 2 | EW6: 35 | EX6: 8 | EY6: 36 | EZ6: 5 | FA6: 29 | FB6: 9 | FC6: 28 | FD6: 2 | FE6: 33 | FF6: 13 | FG6: 47 | FH6: 5 | FI6: 37 | FJ6: 1 | FK6: 19 | FL6: 19 | FM6: 19 | FN6: 2 | FO6: 24 | FP6: 6 | FQ6: 22 | FR6: 4 | FS6: 21 | FT6: 1 | FU6: 32 | FV6: 2 | FW6: 17 | FX6: 3 | FY6: 20 | FZ6: 1 | GA6: 10 | GB6: 2 | GC6: 20 | GD6: 5 | GE6: 18 | GF6: 3 | GG6: 20 | GH6: 4 | GI6: 15 | GJ6: 0 | GK6: 10 | GL6: 5 | GM6: 16 | GN6: 1 | GO6: 16 | GP6: 0 | GQ6: 6 | GR6: 2 | GS6: 10 | GT6: 0 | GU6: 13 | GV6: 2 | GW6: 11 | GX6: 1 | GY6: 9 | GZ6: 1 | HA6: 9 | HB6: 2 | HC6: 13 | HD6: 3 | HE6: 16 | HF6: 1 | HG6: 15 | HH6: 0 | HI6: 4 | HJ6: 2 | HK6: 11 | HL6: 0 | HM6: 6 | HN6: 0 | HO6: 5 | HP6: 0 | HQ6: 5 | HR6: 1 | HS6: 6 | HT6: 0 | HU6: 3 | HV6: 0 | HW6: 0 | HX6: 0 | HY6: 0 | HZ6: 0 | IA6: 0 | IB6: 0 | IC6: 5 | ID6: 1 | IE6: 1 | IF6: 1 | IG6: 1 | IH6: 0 | II6: 2 | IJ6: 0 | IK6: 1 | IL6: 0 | IM6: 1 | IN6: 0 | IO6: 0 | IP6: 0 | IQ6: 2 | IR6: 1 | IS6: 1 | IT6: 0 | IU6: 1 | IV6: 1 | IW6: 3 | IX6: 0 | IY6: 0 | IZ6: 0 | JA6: 0 | JB6: 0 | JC6: 0 | JD6: 0 | JE6: 0
A7: 1.5 | B7: Flex accounts with >=5 £3k+ credits (CR,CQ) and >=4 £3k+ withdrawals (W4,WR) last month. | C7: Accounts with >=5 £3K+ Credits per Month with >=4 £3K+ withdrawal | D7: 3 | E7: 11 | F7: 3 | G7: 6 | H7: 1 | I7: 3 | J7: 3 | K7: 14 | L7: 2 | M7: 5 | N7: 1 | O7: 11 | P7: 0 | Q7: 3 | R7: 0 | S7: 9 | T7: 6 | U7: 26 | V7: 2 | W7: 14 | X7: 1 | Y7: 14 | Z7: 3 | AA7: 9 | AB7: 1 | AC7: 11 | AD7: 0 | AE7: 10 | AF7: 0 | AG7: 3 | AH7: 0 | AI7: 0 | AJ7: 0 | AK7: 0 | AL7: 0 | AM7: 0 | AN7: 0 | AO7: 0 | AP7: 0 | AQ7: 0 | AR7: 1 | AS7: 7 | AT7: 1 | AU7: 8 | AV7: 2 | AW7: 11 | AX7: 1 | AY7: 3 | AZ7: 0 | BA7: 7 | BB7: 0 | BC7: 1 | BD7: 1 | BE7: 1 | BF7: 0 | BG7: 9 | BH7: 0 | BI7: 4 | BJ7: 0 | BK7: 6 | BL7: =0+1 -> 1 | BM7: 6 | BN7: 1 | BO7: 7 | BP7: 0 | BQ7: 5 | BR7: 0 | BS7: 2 | BT7: 2 | BU7: 9 | BV7: 0 | BW7: 6 | BX7: 1 | BY7: 4 | BZ7: 0 | CA7: 4 | CB7: 4 | CC7: 8 | CD7: 1 | CE7: 3 | CF7: 0 | CG7: 4 | CH7: 0 | CI7: 5 | CJ7: 1 | CK7: 5 | CL7: 1 | CM7: 5 | CN7: 1 | CO7: 9 | CP7: 0 | CQ7: 7 | CR7: 1 | CS7: 2 | CT7: 0 | CU7: 2 | CV7: 0 | CW7: 5 | CX7: 1 | CY7: 5 | CZ7: 0 | DA7: 3 | DB7: 1 | DC7: 5 | DD7: 0 | DE7: 2 | DF7: 1 | DG7: 3 | DH7: 1 | DI7: 6 | DJ7: 0 | DK7: 5 | DL7: 2 | DM7: 7 | DN7: 0 | DO7: 2 | DP7: 1 | DQ7: 3 | DR7: 0 | DS7: 5 | DT7: 1 | DU7: 6 | DV7: 0 | DW7: 3 | DX7: 0 | DY7: 4 | DZ7: 0 | EA7: 4 | EB7: 1 | EC7: 6 | ED7: 1 | EE7: 5 | EF7: 0 | EG7: 1 | EH7: 0 | EI7: 5 | EJ7: 1 | EK7: 8 | EL7: 1 | EM7: 3 | EN7: 0 | EO7: 2 | EP7: 0 | EQ7: 3 | ER7: 0 | ES7: 3 | ET7: 1 | EU7: 4
A8: 1.6 | B8: Fixed term Bonds/ISAs closed within 6 months of opening, but after cooling-off period, and Nationwide cheque issued. | C8: Bonds closed within 6 months and Nationwide cheque issued | D8: 0 | E8: 2 | F8: 0 | G8: 4 | H8: 0 | I8: 8 | J8: 0 | K8: 3 | L8: 1 | M8: 14 | N8: 0 | O8: 57 | P8: 0 | Q8: 20 | R8: 0 | S8: 43 | T8: 0 | U8: 47 | V8: 0 | W8: 27 | X8: 0 | Y8: 33 | Z8: 0 | AA8: 2 | AB8: 0 | AC8: 5 | AD8: 0 | AE8: 2 | AF8: 0 | AG8: 6 | AH8: 0 | AI8: 12 | AJ8: 0 | AK8: 9 | AL8: 0 | AM8: 13 | AN8: 0 | AO8: 8 | AP8: 0 | AQ8: 13 | AR8: 0 | AS8: 0 | AT8: 0 | AU8: 9 | AV8: 0 | AW8: 9 | AX8: 0 | AY8: 8 | AZ8: 0 | BA8: 0 | BB8: 0 | BC8: 0 | BD8: 0 | BE8: 0 | BF8: 0 | BG8: 0 | BH8: 0 | BI8: 0 | BJ8: 0 | BK8: 0 | BL8: 0 | BM8: 0 | BN8: 0 | BO8: 0 | BP8: 0 | BQ8: 0 | BR8: 0 | BS8: 0 | BT8: 0 | BU8: 0 | BV8: 0 | BW8: 0 | BX8: 0 | BY8: 0 | BZ8: 0 | CA8: 82 | CB8: 0 | CC8: 88 | CD8: 1 | CE8: 103 | CF8: 0 | CG8: 105 | CH8: 2 | CI8: 87 | CJ8: 1 | CK8: 99 | CL8: 0 | CM8: 148 | CN8: 2 | CO8: 145 | CP8: 1 | CQ8: 162 | CR8: 0 | CS8: 163 | CT8: 1 | CU8: 136 | CV8: 1 | CW8: 125 | CX8: 3 | CY8: 192 | CZ8: 1 | DA8: 233 | DB8: 0 | DC8: 219 | DD8: 0 | DE8: 241
A9: 1.7 | B9: Child accounts with >1 credit (CR, CQ) and at least 1 debit (WA, WD, TW, W4), each £1k+, totalling at least £2k in & £2.5k out last month. | C9: Child accounts with more than £1K in and out in a month | D9: 13 | E9: 41 | F9: 6 | G9: 45 | H9: 9 | I9: 42 | J9: 8 | K9: 45 | L9: 8 | M9: 34 | N9: 7 | O9: 35 | P9: 4 | Q9: 10 | R9: 11 | S9: 40 | T9: 3 | U9: 28 | V9: 12 | W9: 50 | X9: 1 | Y9: 23 | Z9: 1 | AA9: 35 | AB9: 7 | AC9: 27 | AD9: 3 | AE9: 42 | AF9: 5 | AG9: 26 | AH9: 9 | AI9: 43 | AJ9: 8 | AK9: 50 | AL9: 3 | AM9: 27 | AN9: 4 | AO9: 23 | AP9: 3 | AQ9: 41 | AR9: 7 | AS9: 30 | AT9: 4 | AU9: 25 | AV9: 3 | AW9: 20 | AX9: 6 | AY9: 27 | AZ9: 2 | BA9: 11 | BB9: 10 | BC9: 37 | BD9: 7 | BE9: 21 | BF9: 9 | BG9: 27 | BH9: 2 | BI9: 51 | BJ9: 10 | BK9: 24 | BL9: 2 | BM9: 18 | BN9: 2 | BO9: 22 | BP9: 7 | BQ9: 29 | BR9: 5 | BS9: 24 | BT9: 4 | BU9: 31 | BV9: =10+2 -> 12 | BW9: 29 | BX9: 8 | BY9: 15 | BZ9: 13 | CA9: 27 | CB9: 8 | CC9: 18 | CD9: 2 | CE9: 23 | CF9: 7 | CG9: 42 | CH9: 9 | CI9: 31 | CJ9: 8 | CK9: 22 | CL9: 5 | CM9: 21 | CN9: 3 | CO9: 18 | CP9: 4 | CQ9: 18 | CR9: 3 | CS9: 17 | CT9: 4 | CU9: 12 | CV9: 5 | CW9: 19 | CX9: 2 | CY9: 15 | CZ9: 6 | DA9: 16 | DB9: 2 | DC9: 20 | DD9: 9 | DE9: 33 | DF9: 6 | DG9: 18 | DH9: 9 | DI9: 18 | DJ9: 0 | DK9: 12 | DL9: 8 | DM9: 21 | DN9: 5 | DO9: 23 | DP9: 4 | DQ9: 13 | DR9: 6 | DS9: 17 | DT9: 4 | DU9: 12 | DV9: 3 | DW9: 12 | DX9: 3 | DY9: 14 | DZ9: 3 | EA9: 18 | EB9: 1 | EC9: 25 | ED9: 0 | EE9: 11 | EF9: 1 | EG9: 16 | EH9: 2 | EI9: 17 | EJ9: 2 | EK9: 14 | EL9: 0 | EM9: 11 | EN9: 0 | EO9: 9 | EP9: 0 | EQ9: 5 | ER9: 3 | ES9: 13 | ET9: 5 | EU9: 16 | EV9: 0 | EW9: 6 | EX9: 3 | EY9: 14 | EZ9: 1 | FA9: 13 | FB9: 4 | FC9: 12 | FD9: 2 | FE9: 10 | FF9: 3 | FG9: 9 | FH9: 1 | FI9: 20 | FJ9: 3 | FK9: 15 | FL9: 15 | FM9: 15 | FN9: 3 | FO9: 13 | FP9: 4 | FQ9: 9 | FR9: 2 | FS9: 9 | FT9: 6 | FU9: 19 | FV9: 1 | FW9: 10 | FX9: 2 | FY9: 10 | FZ9: 0 | GA9: 19 | GB9: 0 | GC9: 11 | GD9: 2 | GE9: 10 | GF9: 0 | GG9: 5 | GH9: 1 | GI9: 10 | GJ9: 0 | GK9: 12 | GL9: 3 | GM9: 16 | GN9: 0 | GO9: 7 | GP9: 2 | GQ9: 8 | GR9: 2 | GS9: 11 | GT9: 1 | GU9: 9 | GV9: 0 | GW9: 12 | GX9: 1 | GY9: 17 | GZ9: 0 | HA9: 3 | HB9: 2 | HC9: 6 | HD9: 1 | HE9: 14 | HF9: 1 | HG9: 8 | HH9: 3 | HI9: 8 | HJ9: 2 | HK9: 6 | HL9: 0 | HM9: 6 | HN9: 0 | HO9: 7 | HP9: 0 | HQ9: 5 | HR9: 1 | HS9: 3 | HT9: 0 | HU9: 10 | HV9: 0 | HW9: 1 | HX9: 0 | HY9: 2 | HZ9: 0 | IA9: 3 | IB9: 2 | IC9: 8 | ID9: 0 | IE9: 4 | IF9: 3 | IG9: 10 | IH9: 2 | II9: 8 | IJ9: 1 | IK9: 3 | IL9: 1 | IM9: 7 | IN9: 2 | IO9: 2 | IP9: 0 | IQ9: 2 | IR9: 2 | IS9: 8 | IT9: 5 | IU9: 8 | IV9: 1 | IW9: 5 | IX9: 0 | IY9: 4 | IZ9: 2 | JA9: 4 | JB9: 0 | JC9: 4 | JD9: 3 | JE9: 8
A10: 1.11 | B10: Flex accounts of Eastern Europeans, possibly benefits paid (Child Benefit, JSA etc) and may live abroad (2 or more VW in last 3 months). | C10: Flex Accounts of Eastern Europeans, possibly benefits paid (Child Benefit, JSA etc) and may live abroad | P10: 7 | Q10: 68 | T10: 2 | U10: 11 | V10: 3 | W10: 10 | X10: 4 | Y10: 13 | Z10: 1 | AA10: 6 | AB10: 0 | AC10: 8 | AD10: 0 | AE10: 6 | AF10: 0 | AG10: 1 | AH10: 1 | AI10: 8 | AJ10: 1 | AK10: 3 | AL10: 0 | AM10: 0 | AN10: 10 | AO10: 22 | AP10: 3 | AQ10: 12 | AR10: 0 | AS10: 0 | AT10: 2 | AU10: 6 | AV10: 2 | AW10: 5 | AX10: 9 | AY10: 18 | AZ10: 0 | BA10: 0 | BB10: 0 | BC10: 1 | BD10: 0 | BE10: 1 | BF10: 2 | BG10: 3 | BH10: 0 | BI10: 4 | BJ10: 2 | BK10: 2 | BL10: 2 | BM10: 4 | BN10: 0 | BO10: 1 | BP10: 1 | BQ10: 7 | BR10: 0 | BS10: 2 | BT10: 3 | BU10: 16 | BV10: 1 | BW10: 9 | BX10: 4 | BY10: 15 | BZ10: 3 | CA10: 4 | CB10: 3 | CC10: 4 | CD10: 0 | CE10: 2 | CF10: 2 | CG10: 3 | CH10: 0 | CI10: 0 | CJ10: 0 | CK10: 0 | CL10: 0 | CM10: 0 | CN10: 9 | CO10: 11 | CP10: 5 | CQ10: 11 | CR10: 3 | CS10: 6 | CT10: 1 | CU10: 1 | CV10: 9 | CW10: 15 | CX10: 2 | CY10: 5 | CZ10: 6 | DA10: 10 | DB10: 4 | DC10: 7 | DD10: 0 | DE10: 0 | DF10: 0 | DG10: 0 | DH10: 0 | DI10: 0 | DJ10: 0 | DK10: 0 | DL10: 0 | DM10: 0 | DN10: 0 | DO10: 0 | DP10: 0 | DQ10: 0 | DR10: 10 | DS10: 17 | DT10: 6 | DU10: 14 | DV10: 4 | DW10: 8 | DX10: 1 | DY10: 5 | DZ10: 2 | EA10: 11 | EB10: 0 | EC10: 11 | ED10: 2 | EE10: 14 | EF10: 0 | EG10: 12 | EH10: 1 | EI10: 15 | EJ10: 3 | EK10: 23 | EL10: 2 | EM10: 22 | EN10: 2 | EO10: 22 | EP10: 3 | EQ10: 21 | ER10: 1 | ES10: 23 | ET10: 1 | EU10: 17
A11: 1.12 | B11: Debit cards with £2k+ monthly spend on virtual games (includes Second Life, Eve Online and Blizzard). | C11: Debit cards with large (£500+) monthly spend on virtual games | AB11: 0 | AC11: 9 | AD11: 0 | AE11: 4 | AF11: 0 | AG11: 4 | AH11: 1 | AI11: 5 | AJ11: 0 | AK11: 0 | AL11: 0 | AM11: 3 | AN11: 0 | AO11: 4 | AP11: 0 | AQ11: 4 | AR11: 0 | AS11: 5 | AT11: 1 | AU11: 4 | AV11: 0 | AW11: 3 | AX11: 1 | AY11: 4 | AZ11: 1 | BA11: 4 | BB11: 0 | BC11: 3 | BD11: 0 | BE11: 4 | BF11: 0 | BG11: 4 | BH11: 0 | BI11: 4 | BJ11: 0 | BK11: 5 | BL11: 0 | BM11: 4 | BN11: 0 | BO11: 4 | BP11: 0 | BQ11: 5 | BR11: 0 | BS11: 0 | BT11: 0 | BU11: 1 | BV11: 0 | BW11: 1 | BX11: 0 | BY11: 2 | BZ11: 0 | CA11: 5 | CB11: 0 | CC11: 2 | CD11: 0 | CE11: 1 | CF11: 0 | CG11: 2 | CH11: 0 | CI11: 1 | CJ11: 0 | CK11: 0 | CL11: 0 | CM11: 0 | CN11: 0 | CO11: 0 | CP11: 0 | CQ11: 1 | CR11: 0 | CS11: 0 | CT11: 0 | CU11: 0 | CV11: 0 | CW11: 0 | CX11: 0 | CY11: 1 | CZ11: 0 | DA11: 0 | DB11: 0 | DC11: 0 | DD11: 0 | DE11: 0 | DF11: 0 | DG11: 1 | DH11: 0 | DI11: 0 | DJ11: 0 | DK11: 0 | DL11: 0 | DM11: 0 | DN11: 0 | DO11: 0 | DP11: 0 | DQ11: 0 | DR11: 0 | DS11: 0 | DT11: 0 | DU11: 0 | DV11: 0 | DW11: 0 | DX11: 0 | DY11: 0 | DZ11: 0 | EA11: 0 | EB11: 0 | EC11: 0 | ED11: 0 | EE11: 0 | EF11: 0 | EG11: 0 | EH11: 0 | EI11: 0 | EJ11: 0 | EK11: 0 | EL11: 0 | EM11: 0 | EN11: 0 | EO11: 0 | EP11: 0 | EQ11: 0 | ER11: 0 | ES11: 0
A12: 1.13 | B12: Flex accounts receiving 5 or more £3k+ cash credits last month. | C12: Accounts with >=5 £3K+ Cash Credits per Month | AD12: 13 | AE12: 59 | AF12: 1 | AG12: 22 | AH12: 8 | AI12: 28 | AJ12: 3 | AK12: 41 | AL12: 7 | AM12: 28 | AN12: 6 | AO12: 21 | AP12: 3 | AQ12: 41 | AR12: 4 | AS12: 23 | AT12: 2 | AU12: 27 | AV12: 5 | AW12: 52 | AX12: 6 | AY12: 25 | AZ12: 3 | BA12: 30 | BB12: 2 | BC12: 27 | BD12: 3 | BE12: 15 | BF12: 6 | BG12: 23 | BH12: 4 | BI12: 42 | BJ12: 2 | BK12: 25 | BL12: =3+1 -> 4 | BM12: 16 | BN12: 6 | BO12: 47 | BP12: 2 | BQ12: 25 | BR12: 5 | BS12: 26 | BT12: 4 | BU12: 32 | BV12: 4 | BW12: 33 | BX12: 5 | BY12: 32 | BZ12: 2 | CA12: 24 | CB12: 5 | CC12: 18 | CD12: 6 | CE12: 35 | CF12: 2 | CG12: 45 | CH12: 5 | CI12: 27 | CJ12: 4 | CK12: 25 | CL12: 3 | CM12: 35 | CN12: 6 | CO12: 32 | CP12: 7 | CQ12: 47 | CR12: 4 | CS12: 19 | CT12: 9 | CU12: 28 | CV12: 10 | CW12: 45 | CX12: 2 | CY12: 16 | CZ12: 4 | DA12: 12 | DB12: 9 | DC12: 41 | DD12: 9 | DE12: 44 | DF12: 7 | DG12: 25 | DH12: 9 | DI12: 43 | DJ12: 3 | DK12: 28 | DL12: 8 | DM12: 39 | DN12: 10 | DO12: 33 | DP12: 10 | DQ12: 25 | DR12: 6 | DS12: 26 | DT12: 8 | DU12: 40 | DV12: 2 | DW12: 19 | DX12: 2 | DY12: 20 | DZ12: 1 | EA12: 19 | EB12: 17 | EC12: 40 | ED12: 7 | EE12: 44 | EF12: 1 | EG12: 31 | EH12: 1 | EI12: 19 | EJ12: 4 | EK12: 37 | EL12: 3 | EM12: 30 | EN12: 4 | EO12: 19 | EP12: 14 | EQ12: 30 | ER12: 10 | ES12: 26 | ET12: 7 | EU12: 33 | EV12: 1 | EW12: 15 | EX12: 4 | EY12: 26 | EZ12: 4 | FA12: 16 | FB12: 8 | FC12: 44 | FD12: 2 | FE12: 23 | FF12: 9 | FG12: 30 | FH12: 4 | FI12: 25 | FJ12: 7 | FK12: 23 | FL12: 23 | FM12: 23 | FN12: 6 | FO12: 30 | FP12: 6 | FQ12: 22 | FR12: 7 | FS12: 26 | FT12: 8 | FU12: 29 | FV12: 3 | FW12: 25 | FX12: 2 | FY12: 9 | FZ12: 1 | GA12: 15 | GB12: 2 | GC12: 24 | GD12: 4 | GE12: 18 | GF12: 4 | GG12: 18 | GH12: 3 | GI12: 15 | GJ12: 4 | GK12: 18 | GL12: 4 | GM12: 28 | GN12: 0 | GO12: 12 | GP12: 2 | GQ12: 15 | GR12: 3 | GS12: 18 | GT12: 3 | GU12: 11 | GV12: 1 | GW12: 12 | GX12: 5 | GY12: 26 | GZ12: 5 | HA12: 21 | HB12: 2 | HC12: 12 | HD12: 5 | HE12: 25 | HF12: 1 | HG12: 17 | HH12: 0 | HI12: 9 | HJ12: 2 | HK12: 8 | HL12: 0 | HM12: 9 | HN12: 4 | HO12: 17 | HP12: 1 | HQ12: 13 | HR12: 1 | HS12: 13 | HT12: 3 | HU12: 13 | HV12: 1 | HW12: 6 | HX12: 1 | HY12: 6 | HZ12: 1 | IA12: 10 | IB12: 4 | IC12: 13 | ID12: 2 | IE12: 5 | IF12: 0 | IG12: 18 | IH12: 0 | II12: 4 | IJ12: 2 | IK12: 9 | IL12: 1 | IM12: 10 | IN12: 2 | IO12: 6 | IP12: 2 | IQ12: 7 | IR12: 6 | IS12: 10 | IT12: 6 | IU12: 12 | IV12: 0 | IW12: 4 | IX12: 2 | IY12: 10 | IZ12: 3 | JA12: 12 | JB12: 6 | JC12: 15 | JD12: 9 | JE12: 12
A13: 1.14 | B13: Flex accounts where 5+ branches used (CR) and transactions total £2k+ last month. | C13: Flex Accs with 5<>6 branches used and total trans >£2K | AD13: 19 | AE13: 47 | AF13: 25 | AG13: 50 | AH13: 34 | AI13: 60 | AJ13: 20 | AK13: 42 | AL13: 29 | AM13: 72 | AN13: 27 | AO13: 47 | AP13: 18 | AQ13: 40 | AR13: 15 | AS13: 53 | AT13: =43+2 -> 45 | AU13: 86 | AV13: 30 | AW13: 70 | AX13: 22 | AY13: 49 | AZ13: 20 | BA13: 44 | BB13: 25 | BC13: 54 | BD13: 23 | BE13: 57 | BF13: 19 | BG13: 53 | BH13: 26 | BI13: 67 | BJ13: 9 | BK13: 40 | BL13: =24+2 -> 26 | BM13: 59 | BN13: 25 | BO13: 74 | BP13: 22 | BQ13: 68 | BR13: 19 | BS13: 62 | BT13: 30 | BU13: 79 | BV13: 22 | BW13: 49 | BX13: 24 | BY13: 58 | BZ13: 17 | CA13: 51 | CB13: 32 | CC13: 66 | CD13: 36 | CE13: 86 | CF13: 28 | CG13: 65 | CH13: 41 | CI13: 79 | CJ13: 25 | CK13: 68 | CL13: 42 | CM13: 92 | CN13: 26 | CO13: 55 | CP13: 43 | CQ13: 85 | CR13: 38 | CS13: 74 | CT13: 43 | CU13: 71 | CV13: 53 | CW13: 88 | CX13: 27 | CY13: 62 | CZ13: 36 | DA13: 66 | DB13: 43 | DC13: 77 | DD13: 51 | DE13: 88 | DF13: 47 | DG13: 92 | DH13: 42 | DI13: 86 | DJ13: 48 | DK13: 102 | DL13: 51 | DM13: 98 | DN13: 52 | DO13: 84 | DP13: 54 | DQ13: 78 | DR13: 45 | DS13: 78 | DT13: 35 | DU13: 72 | DV13: 34 | DW13: 76 | DX13: 28 | DY13: 75 | DZ13: 34 | EA13: 89 | EB13: 48 | EC13: 93 | ED13: 51 | EE13: 93 | EF13: 32 | EG13: 88 | EH13: 42 | EI13: 101 | EJ13: 47 | EK13: 88 | EL13: 47 | EM13: 108 | EN13: 36 | EO13: 83 | EP13: 61 | EQ13: 95 | ER13: 46 | ES13: 78 | ET13: 48 | EU13: 93 | EV13: 35 | EW13: 69 | EX13: 58 | EY13: 96 | EZ13: 28 | FA13: 56 | FB13: 51 | FC13: 89 | FD13: 36 | FE13: 84 | FF13: 43 | FG13: 96 | FH13: 51 | FI13: 89 | FJ13: 38 | FK13: 94 | FL13: 101 | FM13: 101 | FN13: 53 | FO13: 108 | FP13: 32 | FQ13: 78 | FR13: 32 | FS13: 61 | FT13: 57 | FU13: 112 | FV13: 35 | FW13: 82 | FX13: 13 | FY13: 28 | FZ13: 4 | GA13: 19 | GB13: 6 | GC13: 14 | GD13: 7 | GE13: 18 | GF13: 5 | GG13: 16 | GH13: 3 | GI13: 15 | GJ13: 3 | GK13: 11 | GL13: 3 | GM13: 16 | GN13: 3 | GO13: 13 | GP13: 5 | GQ13: 12 | GR13: 6 | GS13: 22 | GT13: 2 | GU13: 8 | GV13: 5 | GW13: 19 | GX13: 2 | GY13: 11 | GZ13: 2 | HA13: 10 | HB13: 3 | HC13: 14 | HD13: 2 | HE13: 16 | HF13: 5 | HG13: 16 | HH13: 5 | HI13: 14 | HJ13: 5 | HK13: 15 | HL13: 1 | HM13: 11 | HN13: 6 | HO13: 17 | HP13: 5 | HQ13: 16 | HR13: 3 | HS13: 14 | HT13: 1 | HU13: 7 | HV13: 1 | HW13: 1 | HX13: 0 | HY13: 2 | HZ13: 2 | IA13: 7 | IB13: 3 | IC13: 7 | ID13: 1 | IE13: 3 | IF13: 1 | IG13: 5 | IH13: 4 | II13: 5 | IJ13: 1 | IK13: 4 | IL13: 1 | IM13: 2 | IN13: 2 | IO13: 4 | IP13: 0 | IQ13: 0 | IR13: 0 | IS13: 1 | IT13: 1 | IU13: 3 | IV13: 2 | IW13: 4 | IX13: 5 | IY13: 9 | IZ13: 0 | JA13: 5 | JB13: 0 | JC13: 0 | JD13: 4 | JE13: 7
A14: 1.15 | B14: Savings accounts where 5+ branches used (CR) and transactions total £2k+ last month. | C14: Save Accs with 5<>6 branches used | AD14: 10 | AE14: 26 | AF14: 7 | AG14: 37 | AH14: 8 | AI14: 35 | AJ14: 13 | AK14: 41 | AL14: 16 | AM14: 40 | AN14: 13 | AO14: 33 | AP14: 13 | AQ14: 31 | AR14: 11 | AS14: 35 | AT14: 17 | AU14: 52 | AV14: 15 | AW14: 64 | AX14: 13 | AY14: 58 | AZ14: 11 | BA14: 47 | BB14: 16 | BC14: 49 | BD14: 13 | BE14: 47 | BF14: 6 | BG14: 54 | BH14: 15 | BI14: 59 | BJ14: 10 | BK14: 60 | BL14: 9 | BM14: 61 | BN14: 7 | BO14: 61 | BP14: 13 | BQ14: 70 | BR14: 10 | BS14: 42 | BT14: 5 | BU14: 54 | BV14: 4 | BW14: 43 | BX14: 13 | BY14: 48 | BZ14: 12 | CA14: 38 | CB14: 15 | CC14: 43 | CD14: 8 | CE14: 47 | CF14: 8 | CG14: 36 | CH14: 12 | CI14: 52 | CJ14: 9 | CK14: 43 | CL14: 8 | CM14: 60 | CN14: 6 | CO14: 31 | CP14: 5 | CQ14: 48 | CR14: 4 | CS14: 48 | CT14: 10 | CU14: 41 | CV14: 8 | CW14: 34 | CX14: 5 | CY14: 33 | CZ14: 9 | DA14: 39 | DB14: 13 | DC14: 56 | DD14: 14 | DE14: 53 | DF14: 12 | DG14: 35 | DH14: 12 | DI14: 38 | DJ14: 11 | DK14: 47 | DL14: 11 | DM14: 45 | DN14: 12 | DO14: 53 | DP14: 9 | DQ14: 42 | DR14: 14 | DS14: 38 | DT14: 12 | DU14: 34 | DV14: 3 | DW14: 29 | DX14: 7 | DY14: 53 | DZ14: 10 | EA14: 37 | EB14: 12 | EC14: 53 | ED14: 10 | EE14: 34 | EF14: 3 | EG14: 37 | EH14: 7 | EI14: 37 | EJ14: 8 | EK14: 54 | EL14: 8 | EM14: 34 | EN14: 3 | EO14: 29 | EP14: 6 | EQ14: 44 | ER14: 10 | ES14: 37 | ET14: 10 | EU14: 30 | EV14: 5 | EW14: 25 | EX14: 11 | EY14: 38 | EZ14: 8 | FA14: 23 | FB14: 9 | FC14: 39 | FD14: 14 | FE14: 36 | FF14: 10 | FG14: 43 | FH14: 5 | FI14: 24 | FJ14: 7 | FK14: 28 | FL14: 28 | FM14: 28 | FN14: 3 | FO14: 27 | FP14: 3 | FQ14: 8 | FR14: 1 | FS14: 2 | FT14: 2 | FU14: 4 | FV14: 1 | FW14: 4 | FX14: 3 | FY14: 3 | FZ14: 0 | GA14: 3 | GB14: 0 | GC14: 2 | GD14: 0 | GE14: 2 | GF14: 0 | GG14: 4 | GH14: 0 | GI14: 1 | GJ14: 1 | GK14: 2 | GL14: 1 | GM14: 3 | GN14: 0 | GO14: 5 | GP14: 0 | GQ14: 0 | GR14: 1 | GS14: 3 | GT14: 0 | GU14: 4 | GV14: 1 | GW14: 1 | GX14: 0 | GY14: 3 | GZ14: 0 | HA14: 1 | HB14: 0 | HC14: 2 | HD14: 3 | HE14: 3 | HF14: 1 | HG14: 5 | HH14: 0 | HI14: 2 | HJ14: 3 | HK14: 4 | HL14: 0 | HM14: 2 | HN14: 0 | HO14: 1 | HP14: 0 | HQ14: 3 | HR14: 1 | HS14: 2 | HT14: 0 | HU14: 1 | HV14: 0 | HW14: 0 | HX14: 0 | HY14: 0 | HZ14: 0 | IA14: 0 | IB14: 0 | IC14: 0 | ID14: 0 | IE14: 1 | IF14: 1 | IG14: 3 | IH14: 0 | II14: 0 | IJ14: 0 | IK14: 0 | IL14: 0 | IM14: 0 | IN14: 0 | IO14: 0 | IP14: 0 | IQ14: 2 | IR14: 0 | IS14: 0 | IT14: 0 | IU14: 0 | IV14: 0 | IW14: 0 | IX14: 0 | IY14: 0 | IZ14: 0 | JA14: 0 | JB14: 0 | JC14: 0 | JD14: 0 | JE14: 0
A15: 1.16 | B15: Flex accounts receiving £40k+ last month by at least 2 cash credits (CR). | C15: Accounts with >£40K+ Cash Credits per Month | AD15: 8 | AE15: 306 | AF15: 3 | AG15: 40 | AH15: 4 | AI15: 65 | AJ15: 3 | AK15: 55 | AL15: 2 | AM15: 43 | AN15: 1 | AO15: 49 | AP15: 1 | AQ15: 52 | AR15: 1 | AS15: 44 | AT15: 1 | AU15: 52 | AV15: 4 | AW15: 52 | AX15: 2 | AY15: 38 | AZ15: 1 | BA15: 37 | BB15: 2 | BC15: 59 | BD15: 1 | BE15: 24 | BF15: 0 | BG15: 39 | BH15: 2 | BI15: 46 | BJ15: 2 | BK15: 28 | BL15: 0 | BM15: 32 | BN15: 1 | BO15: 50 | BP15: 3 | BQ15: 33 | BR15: 4 | BS15: 41 | BT15: 1 | BU15: 33 | BV15: 0 | BW15: 1 | BX15: 0 | BY15: 41 | BZ15: 2 | CA15: 24 | CB15: 3 | CC15: 17 | CD15: 4 | CE15: 36 | CF15: 2 | CG15: 36 | CH15: 2 | CI15: 20 | CJ15: 5 | CK15: 30 | CL15: 5 | CM15: 40 | CN15: 4 | CO15: 26 | CP15: 3 | CQ15: 37 | CR15: 2 | CS15: 20 | CT15: 6 | CU15: 22 | CV15: 7 | CW15: 36 | CX15: 2 | CY15: 21 | CZ15: 2 | DA15: 10 | DB15: 10 | DC15: 30 | DD15: 2 | DE15: 33 | DF15: 4 | DG15: 24 | DH15: 6 | DI15: 24 | DJ15: 4 | DK15: 22 | DL15: 2 | DM15: 22 | DN15: 1 | DO15: 24 | DP15: 9 | DQ15: 27 | DR15: 4 | DS15: 23 | DT15: 5 | DU15: 33 | DV15: 0 | DW15: 24 | DX15: 2 | DY15: 20 | DZ15: 3 | EA15: 28 | EB15: 11 | EC15: 53 | ED15: 8 | EE15: 49 | EF15: 0 | EG15: 36 | EH15: 3 | EI15: 28 | EJ15: 2 | EK15: 27 | EL15: 1 | EM15: 20 | EN15: 1 | EO15: 18 | EP15: 3 | EQ15: 26 | ER15: 3 | ES15: 21 | ET15: 1 | EU15: 12 | EV15: 0 | EW15: 24 | EX15: 4 | EY15: 36 | EZ15: 5 | FA15: 27 | FB15: 2 | FC15: 22 | FD15: 2 | FE15: 27 | FF15: 4 | FG15: 30 | FH15: 0 | FI15: 19 | FJ15: 3 | FK15: 16 | FL15: 16 | FM15: 16 | FN15: 1 | FO15: 25 | FP15: 2 | FQ15: 10 | FR15: 0 | FS15: 11 | FT15: 4 | FU15: 23 | FV15: 4 | FW15: 10 | FX15: 1 | FY15: 10 | FZ15: 1 | GA15: 11 | GB15: 4 | GC15: 9 | GD15: 2 | GE15: 16 | GF15: 4 | GG15: 11 | GH15: 2 | GI15: 14 | GJ15: 5 | GK15: 10 | GL15: 2 | GM15: 19 | GN15: 0 | GO15: 7 | GP15: 2 | GQ15: 9 | GR15: 0 | GS15: 5 | GT15: 2 | GU15: 8 | GV15: 1 | GW15: 12 | GX15: 3 | GY15: 14 | GZ15: 2 | HA15: 16 | HB15: 0 | HC15: 4 | HD15: 3 | HE15: 21 | HF15: 0 | HG15: 12 | HH15: 0 | HI15: 5 | HJ15: 8 | HK15: 37 | HL15: 4 | HM15: 67 | HN15: 9 | HO15: 65 | HP15: 1 | HQ15: 46 | HR15: 4 | HS15: 56 | HT15: 6 | HU15: 56 | HV15: 2 | HW15: 45 | HX15: 3 | HY15: 56 | HZ15: 3 | IA15: 56 | IB15: 9 | IC15: 68 | ID15: 8 | IE15: 55 | IF15: 4 | IG15: 65 | IH15: 9 | II15: 43 | IJ15: 9 | IK15: 41 | IL15: 3 | IM15: 31 | IN15: Suspended | IO15: Suspended | IP15: Suspended | IQ15: Suspended | IR15: Suspended | IS15: Suspended | IT15: Suspended | IU15: Suspended | IV15: Suspended | IW15: Suspended | IX15: Suspended | IY15: Suspended | IZ15: Suspended | JA15: Suspended | JB15: Suspended | JC15: Suspended | JD15: Suspended | JE15: Suspended
A16: 1.17 | C16: Large No of LAs, C score Flex with CR or WP, Account Recently Opened | AP16: 2 | AQ16: 25
A17: 1.18C | C17: Large No of LAs, C score Flex (>40) | AR17: 9 | AS17: 49 | AT17: 4 | AU17: 16 | AV17: 4 | AW17: 42 | AX17: 5 | AY17: 54
A18: 1.18D | C18: Large No of LAs, D score Flex (>40) | AR18: 7 | AS18: 98 | AT18: 4 | AU18: 31 | AV18: 9 | AW18: 66 | AX18: 4 | AY18: 105
A19: 1.18 | B19: Flex accounts receiving >=30 LAs (each £100+) last month. | C19: Large No of LAs, Flex (>40) | AZ19: 9 | BA19: 82 | BB19: 18 | BC19: 120 | BD19: 8 | BE19: 130 | BF19: 12 | BG19: 133 | BH19: 13 | BI19: 135 | BJ19: 11 | BK19: 179 | BL19: =10+1 -> 11 | BM19: 116 | BN19: 22 | BO19: 200 | BP19: 6 | BQ19: 189 | BR19: 6 | BS19: 123 | BT19: 10 | BU19: 186 | BV19: 25 | BW19: 124 | BX19: 14 | BY19: 57 | BZ19: 7 | CA19: 63 | CB19: 7 | CC19: 39 | CD19: 24 | CE19: 122 | CF19: 14 | CG19: 115 | CH19: 13 | CI19: 114 | CJ19: 14 | CK19: 54 | CL19: 32 | CM19: 172 | CN19: 12 | CO19: 86 | CP19: 17 | CQ19: 106 | CR19: 24 | CS19: 97 | CT19: 30 | CU19: 116 | CV19: 43 | CW19: 156 | CX19: 20 | CY19: 117 | CZ19: 18 | DA19: 71 | DB19: 34 | DC19: 124 | DD19: 36 | DE19: 157 | DF19: 21 | DG19: 87 | DH19: 34 | DI19: 136 | DJ19: 39 | DK19: 170 | DL19: 42 | DM19: 180 | DN19: 27 | DO19: 129 | DP19: 37 | DQ19: 147 | DR19: 25 | DS19: 102 | DT19: 54 | DU19: 202 | DV19: 18 | DW19: 136 | DX19: 32 | DY19: 147 | DZ19: 28 | EA19: 187 | EB19: 49 | EC19: 199 | ED19: 27 | EE19: 135 | EF19: 27 | EG19: 183 | EH19: 29 | EI19: 158 | EJ19: 35 | EK19: 220 | EL19: 34 | EM19: 210 | EN19: 33 | EO19: 139 | EP19: 41 | EQ19: 202 | ER19: 46 | ES19: 225 | ET19: 29 | EU19: 206 | EV19: 30 | EW19: 135 | EX19: 47 | EY19: 279 | EZ19: 35 | FA19: 183 | FB19: 47 | FC19: 263 | FD19: 41 | FE19: 241 | FF19: 47 | FG19: 240 | FH19: 49 | FI19: 282 | FJ19: 38 | FK19: 227 | FL19: 236 | FM19: 236 | FN19: 50 | FO19: 254 | FP19: 55 | FQ19: 302 | FR19: 41 | FS19: 256 | FT19: 54 | FU19: 342 | FV19: 27 | FW19: 196 | FX19: 59 | FY19: 320 | FZ19: 60 | GA19: 287 | GB19: 67 | GC19: 370 | GD19: 51 | GE19: 278 | GF19: 71 | GG19: 282 | GH19: 60 | GI19: 265 | GJ19: 49 | GK19: 218 | GL19: 79 | GM19: 335 | GN19: 69 | GO19: 268 | GP19: 47 | GQ19: 230 | GR19: 61 | GS19: 286 | GT19: 47 | GU19: 199 | GV19: 93 | GW19: 318 | GX19: 84 | GY19: 340 | GZ19: 92 | HA19: 345 | HB19: 66 | HC19: 217 | HD19: 97 | HE19: 324 | HF19: 82 | HG19: 239 | HH19: 48 | HI19: 234 | HJ19: 70 | HK19: 252 | HL19: 64 | HM19: 211 | HN19: 82 | HO19: 222 | HP19: 48 | HQ19: 228 | HR19: 49 | HS19: 180 | HT19: 61 | HU19: 204 | HV19: 96 | HW19: 337 | HX19: 135 | HY19: 423 | HZ19: 130 | IA19: 413 | IB19: 179 | IC19: 484 | ID19: 141 | IE19: 357 | IF19: 122 | IG19: 395 | IH19: 176 | II19: 452 | IJ19: 222 | IK19: 453 | IL19: 220 | IM19: 487 | IN19: 193 | IO19: 413 | IP19: 169 | IQ19: 352 | IR19: 284 | IS19: 601 | IT19: 229 | IU19: 488 | IV19: 189 | IW19: 426 | IX19: 151 | IY19: 367 | IZ19: 200 | JA19: 478 | JB19: 176 | JC19: 446 | JD19: 168 | JE19: 383
A20: 1.19 | B20: Transfers via Chitoro (Zimbabwean money-transfer buisness). | C20: Transfers via Chitoro, Zimbabwe | AR20: 2 | AS20: 23 | AT20: 1 | AU20: 6 | AV20: 0 | AW20: 2 | AX20: 1 | AY20: 25 | AZ20: 0 | BA20: 1 | BB20: 0 | BC20: 1 | BD20: 4 | BE20: 8 | BF20: 0 | BG20: 4 | BH20: 1 | BI20: 5 | BJ20: 1 | BK20: 10 | BL20: 0 | BM20: 4 | BN20: 0 | BO20: 5 | BP20: 0 | BQ20: 7 | BR20: 0 | BS20: 7 | BT20: 0 | BU20: 1 | BV20: 0 | BW20: 0 | BX20: 0 | BY20: 0 | BZ20: 0 | CA20: 3 | CB20: 0 | CC20: 0 | CD20: 0 | CE20: 0 | CF20: 0 | CG20: 0 | CH20: 0 | CI20: 0 | CJ20: 0 | CK20: 0 | CL20: 0 | CM20: 0 | CN20: 0 | CO20: 0 | CP20: 0 | CQ20: 0 | CR20: 0 | CS20: 0 | CT20: 0 | CU20: 0 | CV20: 0 | CW20: 0 | CX20: 0 | CY20: 0 | CZ20: 0 | DA20: 0 | DB20: 0 | DC20: 0 | DD20: 0 | DE20: 0 | DF20: 0 | DG20: 0 | DH20: 0 | DI20: 0 | DJ20: 0 | DK20: 0 | DL20: 0 | DM20: 0 | DN20: 0 | DO20: 0 | DP20: 0 | DQ20: 0 | DR20: 0 | DS20: 0 | DT20: 0 | DU20: 0 | DV20: 0 | DW20: 0 | DX20: 0 | DY20: 0 | DZ20: 0 | EA20: 0 | EB20: 0 | EC20: 0 | ED20: 0 | EE20: 0 | EF20: 0 | EG20: 0 | EH20: 0 | EI20: 0 | EJ20: 0 | EK20: 0 | EL20: 0 | EM20: 0 | EN20: 0 | EO20: 0 | EP20: 0 | EQ20: 0 | ER20: 0 | ES20: 0
A21: 1.20 | C21: £1,000 cash or more via Drop Box | BB21: 4 | BC21: 14 | BD21: 2 | BE21: 11 | BF21: 2 | BG21: 13 | BH21: 2 | BI21: 14 | BJ21: 0 | BK21: 19 | BL21: 3 | BM21: 21 | BN21: 0 | BO21: 0 | BP21: 0 | BQ21: 2
A22: 1.21 | B22: Flex accounts with 40 or more bill payments (WPs), totalling £4.5k or more, last month. | C22: 40 or More WPs in the month | BF22: 1 | BG22: 30 | BH22: 4 | BI22: 23 | BJ22: 5 | BK22: 44 | BL22: 2 | BM22: 25 | BN22: 6 | BO22: 35 | BP22: 1 | BQ22: 44 | BR22: 4 | BS22: 32 | BT22: 4 | BU22: 49 | BV22: 4 | BW22: 34 | BX22: 4 | BY22: 20 | BZ22: 9 | CA22: 46 | CB22: 9 | CC22: 51 | CD22: 11 | CE22: 93 | CF22: 10 | CG22: 120 | CH22: 16 | CI22: 123 | CJ22: 5 | CK22: 59 | CL22: 20 | CM22: 164 | CN22: 12 | CO22: 121 | CP22: 15 | CQ22: 138 | CR22: 18 | CS22: 141 | CT22: 25 | CU22: 122 | CV22: 23 | CW22: 171 | CX22: 15 | CY22: 122 | CZ22: 11 | DA22: 70 | DB22: 24 | DC22: 126 | DD22: 25 | DE22: 178 | DF22: 22 | DG22: 163 | DH22: 28 | DI22: 118 | DJ22: 24 | DK22: 144 | DL22: 27 | DM22: 177 | DN22: 23 | DO22: 126 | DP22: 37 | DQ22: 156 | DR22: 21 | DS22: 127 | DT22: 34 | DU22: 170 | DV22: 14 | DW22: 152 | DX22: 21 | DY22: 131 | DZ22: 31 | EA22: 189 | EB22: 35 | EC22: 197 | ED22: 19 | EE22: 136 | EF22: 25 | EG22: 193 | EH22: 25 | EI22: 168 | EJ22: 29 | EK22: 216 | EL22: 35 | EM22: 205 | EN22: 27 | EO22: 151 | EP22: 36 | EQ22: 195 | ER22: 44 | ES22: 232 | ET22: 41 | EU22: 198 | EV22: 30 | EW22: 159 | EX22: 39 | EY22: 280 | EZ22: 37 | FA22: 216 | FB22: 46 | FC22: 282 | FD22: 35 | FE22: 226 | FF22: 55 | FG22: 261 | FH22: 61 | FI22: 305 | FJ22: 43 | FK22: 300 | FL22: 316 | FM22: 316 | FN22: 46 | FO22: 304 | FP22: 56 | FQ22: 316 | FR22: 40 | FS22: 269 | FT22: 72 | FU22: 342 | FV22: 23 | FW22: 245 | FX22: 70 | FY22: 395 | FZ22: 47 | GA22: 300 | GB22: 73 | GC22: 363 | GD22: 58 | GE22: 366 | GF22: 63 | GG22: 301 | GH22: 55 | GI22: 306 | GJ22: 52 | GK22: 241 | GL22: 70 | GM22: 380 | GN22: 64 | GO22: 311 | GP22: 56 | GQ22: 288 | GR22: 57 | GS22: 268 | GT22: 31 | GU22: 143 | GV22: 79 | GW22: 304 | GX22: 74 | GY22: 293 | GZ22: 80 | HA22: 282 | HB22: 60 | HC22: 231 | HD22: 90 | HE22: 277 | HF22: 103 | HG22: 260 | HH22: 74 | HI22: 239 | HJ22: 74 | HK22: 195 | HL22: 55 | HM22: 226 | HN22: 77 | HO22: 252 | HP22: 49 | HQ22: 279 | HR22: 70 | HS22: 187 | HT22: 90 | HU22: 237 | HV22: 124 | HW22: 327 | HX22: 139 | HY22: 423 | HZ22: 141 | IA22: 429 | IB22: 202 | IC22: 494 | ID22: 172 | IE22: 409 | IF22: 164 | IG22: 407 | IH22: 207 | II22: 490 | IJ22: 275 | IK22: 530 | IL22: 292 | IM22: 635 | IN22: 257 | IO22: 485 | IP22: 264 | IQ22: 509 | IR22: 389 | IS22: 773 | IT22: 294 | IU22: 666 | IV22: 283 | IW22: 566 | IX22: 268 | IY22: 522 | IZ22: 282 | JA22: 625 | JB22: 242 | JC22: 578 | JD22: 266 | JE22: 569
A23: 1.22 | B23: Multiple (4+) Chaps/Swifts received totalling £10k or more. | C23: Multiple Chaps/Swifts received totalling £10K or more | BF23: 9 | BG23: 92 | BH23: 8 | BI23: 96 | BJ23: 11 | BK23: 103 | BL23: =5+1 -> 6 | BM23: 75 | BN23: 6 | BO23: 96 | BP23: 0 | BQ23: 57 | BR23: 11 | BS23: 71 | BT23: 9 | BU23: 89 | BV23: 8 | BW23: 66 | BX23: 9 | BY23: 83 | BZ23: 3 | CA23: 91 | CB23: 9 | CC23: 67 | CD23: 10 | CE23: 100 | CF23: 16 | CG23: 100 | CH23: 8 | CI23: 99 | CJ23: 9 | CK23: 70 | CL23: 6 | CM23: 97 | CN23: 16 | CO23: 78 | CP23: 9 | CQ23: 97 | CR23: 10 | CS23: 87 | CT23: 11 | CU23: 80 | CV23: 13 | CW23: 101 | CX23: 6 | CY23: 73 | CZ23: 13 | DA23: 70 | DB23: 18 | DC23: 98 | DD23: 15 | DE23: 92 | DF23: 12 | DG23: 68 | DH23: 18 | DI23: 111 | DJ23: 15 | DK23: 99 | DL23: 11 | DM23: 70 | DN23: 12 | DO23: 94 | DP23: 13 | DQ23: 75 | DR23: 19 | DS23: 80 | DT23: 18 | DU23: 109 | DV23: 5 | DW23: 76 | DX23: 4 | DY23: 94 | DZ23: 11 | EA23: 117 | EB23: 2 | EC23: 92 | ED23: 2 | EE23: 74 | EF23: 7 | EG23: 142 | EH23: 7 | EI23: 111 | EJ23: 4 | EK23: 113 | EL23: 7 | EM23: 88 | EN23: 5 | EO23: 79 | EP23: 6 | EQ23: 87 | ER23: 8 | ES23: 126 | ET23: 14 | EU23: 116 | EV23: 15 | EW23: 106 | EX23: 11 | EY23: 143 | EZ23: 11 | FA23: 77 | FB23: 19 | FC23: 175 | FD23: 12 | FE23: 150 | FF23: 7 | FG23: 109 | FH23: 11 | FI23: 127 | FJ23: 4 | FK23: 105 | FL23: 105 | FM23: 105 | FN23: 10 | FO23: 115 | FP23: 17 | FQ23: 139 | FR23: 11 | FS23: 139 | FT23: 14 | FU23: 144 | FV23: 8 | FW23: 97 | FX23: 19 | FY23: 130 | FZ23: 19 | GA23: 138 | GB23: 15 | GC23: 158 | GD23: 13 | GE23: 117 | GF23: 13 | GG23: 86 | GH23: 14 | GI23: 82 | GJ23: 9 | GK23: 57 | GL23: 9 | GM23: 80 | GN23: 19 | GO23: 106 | GP23: 7 | GQ23: 75 | GR23: 5 | GS23: 58 | GT23: 8 | GU23: 59 | GV23: 18 | GW23: 72 | GX23: 9 | GY23: 89 | GZ23: 16 | HA23: 93 | HB23: 8 | HC23: 64 | HD23: 9 | HE23: 53 | HF23: 5 | HG23: 35 | HH23: 7 | HI23: 31 | HJ23: 7 | HK23: 29 | HL23: 8 | HM23: 42 | HN23: 8 | HO23: 31 | HP23: 9 | HQ23: 38 | HR23: 9 | HS23: 34 | HT23: 10 | HU23: 56 | HV23: 5 | HW23: 23 | HX23: 5 | HY23: 24 | HZ23: 7 | IA23: 31 | IB23: 12 | IC23: 49 | ID23: 6 | IE23: 32 | IF23: 16 | IG23: 60 | IH23: 8 | II23: 39 | IJ23: 10 | IK23: 33 | IL23: 5 | IM23: 38 | IN23: 4 | IO23: 21 | IP23: 9 | IQ23: 13 | IR23: 6 | IS23: 18 | IT23: 6 | IU23: 19 | IV23: 4 | IW23: 12 | IX23: 8 | IY23: 28 | IZ23: 1 | JA23: 19 | JB23: 7 | JC23: 27 | JD23: 6 | JE23: 31
A24: 1.23 | B24: 10 or more WPs (totalling at least £4.5k) and 2+ Chaps/Swifts (C7s), totalling at least £10k, last month. | C24: 10 or More WPs and 4+ Chaps ge £10K in the month | BL24: 0 | BM24: 1 | BN24: 2 | BO24: 11 | BP24: 0 | BQ24: 1 | BR24: 3 | BS24: 11 | BT24: 0 | BU24: 3 | BV24: 2 | BW24: 4 | BX24: 3 | BY24: 7 | BZ24: 0 | CA24: 14 | CB24: 1 | CC24: 24 | CD24: 3 | CE24: 34 | CF24: 3 | CG24: 16 | CH24: 0 | CI24: 16 | CJ24: 1 | CK24: 11 | CL24: 0 | CM24: 14 | CN24: 11 | CO24: 84 | CP24: 9 | CQ24: 103 | CR24: 10 | CS24: 111 | CT24: 3 | CU24: 70 | CV24: 12 | CW24: 142 | CX24: 9 | CY24: 93 | CZ24: 28 | DA24: 97 | DB24: 13 | DC24: 102 | DD24: 6 | DE24: 107 | DF24: 13 | DG24: 112 | DH24: 14 | DI24: 86 | DJ24: 5 | DK24: 77 | DL24: 6 | DM24: 66 | DN24: 10 | DO24: 81 | DP24: 8 | DQ24: 75 | DR24: 10 | DS24: 77 | DT24: 12 | DU24: 107 | DV24: 5 | DW24: 91 | DX24: 4 | DY24: 77 | DZ24: 8 | EA24: 114 | EB24: 9 | EC24: 89 | ED24: 2 | EE24: 83 | EF24: 4 | EG24: 103 | EH24: 4 | EI24: 97 | EJ24: 6 | EK24: 85 | EL24: 3 | EM24: 84 | EN24: 3 | EO24: 78 | EP24: 9 | EQ24: 91 | ER24: 9 | ES24: 98 | ET24: 10 | EU24: 110 | EV24: 4 | EW24: 92 | EX24: 9 | EY24: 116 | EZ24: 7 | FA24: 81 | FB24: 16 | FC24: 142 | FD24: 9 | FE24: 111 | FF24: 5 | FG24: 111 | FH24: 6 | FI24: 97 | FJ24: 0 | FK24: 87 | FL24: 87 | FM24: 87
A25: 1.24 | B25: New (2 months or less) and sole account with NW, with CQ paid in and closed. | C25: New Accounts with CQ paid in and closed | BL25: 0 | BM25: 0 | BN25: 1 | BO25: 1 | BP25: 0 | BQ25: 0 | BR25: 0 | BS25: 0 | BT25: 0 | BU25: 15 | BV25: 0 | BW25: 0 | BX25: 3 | BY25: 39 | BZ25: 0 | CA25: 53 | CB25: 0 | CC25: 56 | CD25: 3 | CE25: 84 | CF25: 2 | CG25: 75 | CH25: 3 | CI25: 63 | CJ25: 1 | CK25: 68 | CL25: 3 | CM25: 41 | CN25: 1 | CO25: 53 | CP25: 2 | CQ25: 41 | CR25: 5 | CS25: 42 | CT25: 1 | CU25: 40 | CV25: 0 | CW25: 19 | CX25: 1 | CY25: 23 | CZ25: 5 | DA25: 27 | DB25: 5 | DC25: 30 | DD25: 2 | DE25: 27 | DF25: 7 | DG25: 38 | DH25: 1 | DI25: 20 | DJ25: 7 | DK25: 47 | DL25: 2 | DM25: 24 | DN25: 2 | DO25: 38 | DP25: 1 | DQ25: 28 | DR25: 0 | DS25: 27 | DT25: 2 | DU25: 35 | DV25: 2 | DW25: 21 | DX25: 0 | DY25: 41 | DZ25: 0 | EA25: 49 | EB25: 0 | EC25: 26 | ED25: 1 | EE25: 25 | EF25: 0 | EG25: 34 | EH25: 1 | EI25: 33 | EJ25: 3 | EK25: 46 | EL25: 0 | EM25: 30 | EN25: 0 | EO25: 16 | EP25: 0 | EQ25: 15 | ER25: 0 | ES25: 13 | ET25: 1 | EU25: 21 | EV25: 0 | EW25: 27 | EX25: 0 | EY25: 27 | EZ25: 0 | FA25: 53 | FB25: 1 | FC25: 21 | FD25: 2 | FE25: 11 | FF25: 0 | FG25: 26 | FH25: 1 | FI25: 29 | FJ25: 0 | FK25: 25 | FL25: 32 | FM25: 32 | FN25: Suspended | FO25: Suspended | FP25: Suspended | FQ25: Suspended | FR25: Suspended | FS25: Suspended | FT25: Suspended | FU25: Suspended | FV25: Suspended | FW25: Suspended | FX25: Suspended | FY25: Suspended | FZ25: Suspended | GA25: Suspended | GB25: Suspended | GC25: Suspended | GD25: Suspended | GE25: Suspended | GF25: Suspended | GG25: Suspended | GH25: Suspended | GI25: Suspended | GJ25: Suspended | GK25: Suspended | GL25: Suspended | GM25: Suspended | GN25: Suspended | GO25: Suspended | GP25: Suspended | GQ25: Suspended | GR25: Suspended | GS25: Suspended | GT25: Suspended | GU25: Suspended | GV25: Suspended | GW25: Suspended | GX25: Suspended | GY25: Suspended | GZ25: Suspended | HA25: Suspended | HB25: Suspended | HC25: Suspended | HD25: Suspended | HE25: Suspended | HF25: Suspended | HG25: Suspended | HH25: Suspended | HI25: Suspended | HJ25: Suspended | HK25: Suspended | HL25: Suspended | HM25: Suspended | HN25: Suspended | HO25: Suspended | HP25: Suspended | HQ25: Suspended | HR25: Suspended | HS25: Suspended | HT25: Suspended | HU25: Suspended | HV25: Suspended | HW25: Suspended | HX25: Suspended | HY25: Suspended | HZ25: Suspended | IA25: Suspended | IB25: Suspended | IC25: Suspended | ID25: Suspended | IE25: Suspended | IF25: Suspended | IG25: Suspended | IH25: Suspended | II25: Suspended | IJ25: Suspended | IK25: Suspended | IL25: Suspended | IM25: Suspended | IN25: Suspended | IO25: Suspended | IP25: Suspended | IQ25: Suspended | IR25: Suspended | IS25: Suspended | IT25: Suspended | IU25: Suspended | IV25: Suspended | IW25: Suspended | IX25: Suspended | IY25: Suspended | IZ25: Suspended | JA25: Suspended | JB25: Suspended | JC25: Suspended | JD25: Suspended | JE25: Suspended
A26: 1.25 | B26: Debit card purchase (£300+ per transaction and £2.5k+ in total) of large amount of booze/fags - Europe over past 3 months. | C26: Debit Card Purchase of large amount of Booze/Fags -Europe | BX26: 0 | BY26: 2 | BZ26: 0 | CA26: 5 | CB26: 0 | CC26: 2 | CD26: 0 | CE26: 0 | CF26: 0 | CG26: 0 | CH26: 0 | CI26: 0 | CJ26: 3 | CK26: 5 | CL26: 0 | CM26: 5 | CN26: 0 | CO26: 3 | CP26: 1 | CQ26: 1 | CR26: 0 | CS26: 0 | CT26: 0 | CU26: 0 | CV26: 0 | CW26: 1 | CX26: 1 | CY26: 2 | CZ26: 1 | DA26: 1 | DB26: 1 | DC26: 5 | DD26: 1 | DE26: 3 | DF26: 1 | DG26: 1 | DH26: 1 | DI26: 4 | DJ26: 0 | DK26: 0 | DL26: 2 | DM26: 5 | DN26: 1 | DO26: 2 | DP26: 1 | DQ26: 2 | DR26: 2 | DS26: 4 | DT26: 2 | DU26: 2 | DV26: 2 | DW26: 4 | DX26: 1 | DY26: 1 | DZ26: 1 | EA26: 3 | EB26: 0 | EC26: 2 | ED26: 0 | EE26: 3 | EF26: 1 | EG26: 2 | EH26: 2 | EI26: 4 | EJ26: 0 | EK26: 2 | EL26: 0 | EM26: 3 | EN26: 1 | EO26: 5 | EP26: 5 | EQ26: 5 | ER26: 0 | ES26: 0 | ET26: 0 | EU26: 0 | EV26: 4 | EW26: 10 | EX26: 4 | EY26: 6 | EZ26: 2 | FA26: 2 | FB26: 1 | FC26: 2 | FD26: 2 | FE26: 2 | FF26: 2 | FG26: 4 | FH26: 1 | FI26: 2 | FJ26: 4 | FK26: 7 | FL26: 7 | FM26: 7 | FN26: 2 | FO26: 2 | FP26: 0 | FQ26: 2 | FR26: 1 | FS26: 1 | FT26: 2 | FU26: 4 | FV26: 2 | FW26: 2 | FX26: 0 | FY26: 4 | FZ26: 2 | GA26: 2 | GB26: 0 | GC26: 0 | GD26: 1 | GE26: 2 | GF26: 1 | GG26: 5 | GH26: 1 | GI26: 4 | GJ26: 0 | GK26: 2 | GL26: 3 | GM26: 4 | GN26: 1 | GO26: 4 | GP26: 5 | GQ26: 9 | GR26: 0 | GS26: 0 | GT26: 1 | GU26: 2 | GV26: 1 | GW26: 6 | GX26: 0 | GY26: 1 | GZ26: 1 | HA26: 4 | HB26: 3 | HC26: 4 | HD26: 1 | HE26: 1 | HF26: 0 | HG26: 0 | HH26: 0 | HI26: 0 | HJ26: 0 | HK26: 0 | HL26: 0 | HM26: 0 | HN26: 0 | HO26: 0 | HP26: 0 | HQ26: 0 | HR26: 0 | HS26: 0 | HT26: 0 | HU26: 0 | HV26: 0 | HW26: 0 | HX26: 0 | HY26: 0 | HZ26: 0 | IA26: 0 | IB26: 0 | IC26: 0 | ID26: 0 | IE26: 0
A27: 1.26 | B27: Treasurers Trust with high proportion (40% or greater) of cash WDs & balance of £5k+. | C27: Treasureres Trust with High proportion of cash WD | CB27: 0 | CC27: 11 | CD27: 0 | CE27: 12 | CF27: 2 | CG27: 4 | CH27: 1 | CI27: 10 | CJ27: 0 | CK27: 10 | CL27: 1 | CM27: 21 | CN27: 0 | CO27: 13 | CP27: 0 | CQ27: 9 | CR27: 1 | CS27: 13 | CT27: 1 | CU27: 25 | CV27: 2 | CW27: 24 | CX27: 0 | CY27: 8 | CZ27: 1 | DA27: 12 | DB27: 0 | DC27: 11 | DD27: 1 | DE27: 14 | DF27: 0 | DG27: 17 | DH27: 1 | DI27: 14 | DJ27: 2 | DK27: 16 | DL27: 1 | DM27: 9 | DN27: 0 | DO27: 7 | DP27: 1 | DQ27: 18 | DR27: 0 | DS27: 11 | DT27: 0 | DU27: 19 | DV27: 0 | DW27: 8 | DX27: 0 | DY27: 14 | DZ27: 0 | EA27: 11 | EB27: 1 | EC27: 8 | ED27: 1 | EE27: 7 | EF27: 0 | EG27: 20 | EH27: 0 | EI27: 10 | EJ27: 0 | EK27: 7 | EL27: 1 | EM27: 6 | EN27: 1 | EO27: 12 | EP27: 0 | EQ27: 19 | ER27: 0 | ES27: 12 | ET27: 1 | EU27: 7 | EV27: 0 | EW27: 8 | EX27: 0 | EY27: 8 | EZ27: 0 | FA27: 3 | FB27: 0 | FC27: 9 | FD27: 0 | FE27: 10 | FF27: 0 | FG27: 14 | FH27: 0 | FI27: 10 | FJ27: 0 | FK27: 5 | FL27: 7 | FM27: 7 | FN27: 0 | FO27: 11 | FP27: 0 | FQ27: 17 | FR27: 0 | FS27: 12 | FT27: 0 | FU27: 2 | FV27: 0 | FW27: 8 | FX27: 0 | FY27: 5 | FZ27: 0 | GA27: 10 | GB27: 0 | GC27: 7 | GD27: 0 | GE27: 7 | GF27: 0 | GG27: 2 | GH27: 1 | GI27: 6 | GJ27: 0 | GK27: 7 | GL27: 0 | GM27: 11 | GN27: 0 | GO27: 24 | GP27: 0 | GQ27: 6 | GR27: 0 | GS27: 4 | GT27: 0 | GU27: 4 | GV27: 0 | GW27: 11 | GX27: 0 | GY27: 5 | GZ27: 0 | HA27: 4 | HB27: 0 | HC27: 7 | HD27: 0 | HE27: 9 | HF27: 0 | HG27: 5 | HH27: 0 | HI27: 6 | HJ27: 0 | HK27: 4 | HL27: 0 | HM27: 9 | HN27: 0 | HO27: 11 | HP27: 0 | HQ27: 6 | HR27: 0 | HS27: 4 | HT27: 0 | HU27: 5 | HV27: 0 | HW27: 1 | HX27: 0 | HY27: 3 | HZ27: 0 | IA27: 2 | IB27: 0 | IC27: 4 | ID27: 0 | IE27: 3 | IF27: 0 | IG27: 4 | IH27: 0 | II27: 4 | IJ27: 0 | IK27: 6 | IL27: 0 | IM27: 6 | IN27: 0 | IO27: 3 | IP27: 0 | IQ27: 1 | IR27: 0 | IS27: 3 | IT27: 0 | IU27: 5 | IV27: 0 | IW27: 4 | IX27: 1 | IY27: 5 | IZ27: 0 | JA27: 2 | JB27: 0 | JC27: 4 | JD27: 0 | JE27: 3
A28: 1.27 | B28: Accounts with £50k+ in and out via LAs (between 10-29), WPs & VPs (WP+VP 25 plus). | C28: Accounts with 50K plus in and Out via LA, WP, VP | CH28: 10 | CI28: 66 | CJ28: 6 | CK28: 55 | CL28: 7 | CM28: 84 | CN28: 4 | CO28: 49 | CP28: 5 | CQ28: 74 | CR28: 4 | CS28: 93 | CT28: 7 | CU28: 67 | CV28: 10 | CW28: 77 | CX28: 4 | CY28: 75 | CZ28: 6 | DA28: 50 | DB28: 9 | DC28: 63 | DD28: 8 | DE28: 91 | DF28: 7 | DG28: 82 | DH28: 8 | DI28: 92 | DJ28: 20 | DK28: 114 | DL28: 9 | DM28: 104 | DN28: 11 | DO28: 106 | DP28: 12 | DQ28: 115 | DR28: 6 | DS28: 128 | DT28: 12 | DU28: 114 | DV28: 7 | DW28: 104 | DX28: 8 | DY28: 108 | DZ28: 7 | EA28: 146 | EB28: 9 | EC28: 127 | ED28: 5 | EE28: 114 | EF28: 5 | EG28: 123 | EH28: 2 | EI28: 114 | EJ28: 7 | EK28: 152 | EL28: 5 | EM28: 130 | EN28: 10 | EO28: 103 | EP28: 5 | EQ28: 144 | ER28: 8 | ES28: 132 | ET28: 10 | EU28: 153 | EV28: 11 | EW28: 127 | EX28: 8 | EY28: 208 | EZ28: 13 | FA28: 141 | FB28: 11 | FC28: 181 | FD28: 9 | FE28: 172 | FF28: 11 | FG28: 199 | FH28: 10 | FI28: 193 | FJ28: 2 | FK28: 203 | FL28: 206 | FM28: 206 | FN28: Suspended | FO28: Suspended | FP28: Suspended | FQ28: Suspended | FR28: Suspended | FS28: Suspended | FT28: Suspended | FU28: Suspended | FV28: Suspended | FW28: Suspended | FX28: Suspended | FY28: Suspended | FZ28: Suspended | GA28: Suspended | GB28: Suspended | GC28: Suspended | GD28: Suspended | GE28: Suspended | GF28: Suspended | GG28: Suspended | GH28: Suspended | GI28: Suspended | GJ28: Suspended | GK28: Suspended | GL28: Suspended | GM28: Suspended | GN28: Suspended | GO28: Suspended | GP28: Suspended | GQ28: Suspended | GR28: Suspended | GS28: Suspended | GT28: Suspended | GU28: Suspended | GV28: Suspended | GW28: Suspended | GX28: Suspended | GY28: Suspended | GZ28: Suspended | HA28: Suspended | HB28: Suspended | HC28: Suspended | HD28: Suspended | HE28: Suspended | HF28: Suspended | HG28: Suspended | HH28: Suspended | HI28: Suspended | HJ28: Suspended | HK28: Suspended | HL28: Suspended | HM28: Suspended | HN28: Suspended | HO28: Suspended | HP28: Suspended | HQ28: Suspended | HR28: Suspended | HS28: Suspended | HT28: Suspended | HU28: Suspended | HV28: Suspended | HW28: Suspended | HX28: Suspended | HY28: Suspended | HZ28: Suspended | IA28: Suspended | IB28: Suspended | IC28: Suspended | ID28: Suspended | IE28: Suspended | IF28: Suspended | IG28: Suspended | IH28: Suspended | II28: Suspended | IJ28: Suspended | IK28: Suspended | IL28: Suspended | IM28: Suspended | IN28: Suspended | IO28: Suspended | IP28: Suspended | IQ28: Suspended | IR28: Suspended | IS28: Suspended | IT28: Suspended | IU28: Suspended | IV28: Suspended | IW28: Suspended | IX28: Suspended | IY28: Suspended | IZ28: Suspended | JA28: Suspended | JB28: Suspended | JC28: Suspended | JD28: Suspended | JE28: Suspended
A29: 1.28 | B29: Treasurers Trust, Business Investor and Portfolio Investor accounts conducting Swifts. | C29: Organisation Accounts with Swifts | CV29: 0 | CW29: 11 | CX29: 0 | CY29: 6 | CZ29: 0 | DA29: 7 | DB29: 0 | DC29: 7 | DD29: 0 | DE29: 4 | DF29: 1 | DG29: 7 | DH29: 0 | DI29: 9 | DJ29: 0 | DK29: 3 | DL29: 2 | DM29: 9 | DN29: 2 | DO29: 9 | DP29: 1 | DQ29: 7 | DR29: 0 | DS29: 7 | DT29: 0 | DU29: 5 | DV29: 0 | DW29: 8 | DX29: 0 | DY29: 7 | DZ29: 0 | EA29: 5 | EB29: 0 | EC29: 8 | ED29: 0 | EE29: 12 | EF29: 0 | EG29: 6 | EH29: 0 | EI29: 6 | EJ29: 0 | EK29: 3 | EL29: 0 | EM29: 7 | EN29: 0 | EO29: 6 | EP29: 1 | EQ29: 6 | ER29: 0 | ES29: 4 | ET29: 1 | EU29: 5 | EV29: 0 | EW29: 5 | EX29: 0 | EY29: 1 | EZ29: 0 | FA29: 2 | FB29: 0 | FC29: 0 | FD29: 0 | FE29: 2 | FF29: 0 | FG29: 1 | FH29: 0 | FI29: 1 | FJ29: 0 | FK29: 1 | FL29: 1 | FM29: 1 | FN29: 0 | FO29: 2 | FP29: 0 | FQ29: 2 | FR29: 0 | FS29: 1 | FT29: 0 | FU29: 1 | FV29: 0 | FW29: 0 | FX29: 0 | FY29: 0 | FZ29: 0 | GA29: 3 | GB29: 0 | GC29: 0 | GD29: 0 | GE29: 1 | GF29: 0 | GG29: 0 | GH29: 0 | GI29: 1 | GJ29: 0 | GK29: 1 | GL29: 0 | GM29: 0 | GN29: 0 | GO29: 0 | GP29: 0 | GQ29: 1 | GR29: 0 | GS29: 1 | GT29: 0 | GU29: 0 | GV29: 0 | GW29: 0 | GX29: 0 | GY29: 0 | GZ29: 0 | HA29: 1 | HB29: 0 | HC29: 0 | HD29: 0 | HE29: 1 | HF29: 0 | HG29: 1 | HH29: 0 | HI29: 0 | HJ29: 0 | HK29: 1 | HL29: 0 | HM29: 1 | HN29: 0 | HO29: 0 | HP29: 0 | HQ29: 0 | HR29: 0 | HS29: 0 | HT29: 0 | HU29: 1 | HV29: 0 | HW29: 0 | HX29: 0 | HY29: 0 | HZ29: 0 | IA29: 0 | IB29: 0 | IC29: 0 | ID29: 0 | IE29: 1 | IF29: 0 | IG29: 0 | IH29: 0 | II29: 0 | IJ29: 0 | IK29: 0 | IL29: 0 | IM29: 0 | IN29: 0 | IO29: 0 | IP29: 0 | IQ29: 0 | IR29: 0 | IS29: 0 | IT29: 0 | IU29: 0 | IV29: 0 | IW29: 0 | IX29: 0 | IY29: 0 | IZ29: 0 | JA29: 0 | JB29: 0 | JC29: 0 | JD29: 0 | JE29: 0
A30: 1.29 | B30: Accounts with a £40k+ turnover, where 80%+ of debit value is withdrawn via WP or Cash, receiving 20+ credits (each £900+) last month. | DB30: 45 | DC30: 198 | DD30: 27 | DE30: 93 | DF30: 13 | DG30: 79 | DH30: 24 | DI30: 96 | DJ30: 37 | DK30: 142 | DL30: 25 | DM30: 152 | DN30: 22 | DO30: 105 | DP30: 20 | DQ30: 91 | DR30: 18 | DS30: 94 | DT30: 23 | DU30: 111 | DV30: 12 | DW30: 96 | DX30: 13 | DY30: 101 | DZ30: 17 | EA30: 144 | EB30: 22 | EC30: 125 | ED30: 18 | EE30: 106 | EF30: 19 | EG30: 132 | EH30: 13 | EI30: 104 | EJ30: 18 | EK30: 135 | EL30: 15 | EM30: 102 | EN30: 11 | EO30: 93 | EP30: 22 | EQ30: 136 | ER30: 17 | ES30: 119 | ET30: 15 | EU30: 113 | EV30: 16 | EW30: 93 | EX30: 19 | EY30: 164 | EZ30: 14 | FA30: 137 | FB30: 20 | FC30: 138 | FD30: 19 | FE30: 128 | FF30: 15 | FG30: 130 | FH30: 29 | FI30: 189 | FJ30: 31 | FK30: 195 | FL30: 200 | FM30: 200 | FN30: 16 | FO30: 94 | FP30: 13 | FQ30: 83 | FR30: 3 | FS30: 83 | FT30: 13 | FU30: 108 | FV30: 8 | FW30: 81 | FX30: 25 | FY30: 99 | FZ30: 14 | GA30: 89 | GB30: 25 | GC30: 107 | GD30: 13 | GE30: 87 | GF30: 13 | GG30: 82 | GH30: 11 | GI30: 110 | GJ30: 9 | GK30: 66 | GL30: 16 | GM30: 132 | GN30: 11 | GO30: 104 | GP30: 12 | GQ30: 100 | GR30: 19 | GS30: 118 | GT30: 10 | GU30: 85 | GV30: 16 | GW30: 94 | GX30: 11 | GY30: 128 | GZ30: 17 | HA30: 101 | HB30: 11 | HC30: 91 | HD30: 17 | HE30: 94 | HF30: 11 | HG30: 103 | HH30: 0 | HI30: 25 | HJ30: 0 | HK30: 27 | HL30: 3 | HM30: 40 | HN30: 1 | HO30: 32 | HP30: 4 | HQ30: 31 | HR30: 2 | HS30: 17 | HT30: 6 | HU30: 42 | HV30: 7 | HW30: 61 | HX30: 7 | HY30: 61 | HZ30: 11 | IA30: 52 | IB30: 19 | IC30: 67 | ID30: 15 | IE30: 54 | IF30: 7 | IG30: 41 | IH30: 20 | II30: 69 | IJ30: 10 | IK30: 59 | IL30: 14 | IM30: 54 | IN30: Suspended | IO30: Suspended | IP30: Suspended | IQ30: Suspended | IR30: Suspended | IS30: Suspended | IT30: Suspended | IU30: Suspended | IV30: Suspended | IW30: Suspended | IX30: Suspended | IY30: Suspended | IZ30: Suspended | JA30: Suspended | JB30: Suspended | JC30: Suspended | JD30: Suspended | JE30: Suspended
B31: Banking Total | C31: Banking Total | D31: =SUM(D3:D30) -> 80 | E31: =SUM(E3:E30) -> 183 | F31: =SUM(F3:F30) -> 39 | G31: =SUM(G3:G30) -> 128 | H31: =SUM(H3:H30) -> 33 | I31: =SUM(I3:I30) -> 132 | J31: =SUM(J3:J30) -> 59 | K31: =SUM(K3:K30) -> 223 | ... JE31: =SUM(JE3:JE30) -> 1019
